Workbook

Sheet BASIC INFO
A1: IOWA CRIMINAL RECORD SPREADSHEET, (CRS) © 2017 ALEX KORNYA, ALL RIGHTS RESERVED | D1: VERSION 3.5 | H1: NOTE: Designed for Excel 2016, some functions may not work properly in earlier versions.
A3: DATE OF CLINIC / CLIENT MEETING
A4: PREPARER NAME
A5: CLIENT NAME
A6: CLIENT DOB
A7: CHECKED BY
A8: CHECK DATE
D11: DISCLAIMER: This spreadsheet is intended to be a tool to assist with the gathering and analysis of criminal record information. It is NOT meant to constitute legal advice in any way, and there cannot and should not be relied upon. If you are seeking analysis of your legal rights and responsibilities, you are urged to contact an attorney.

Sheet CASE DATA
A1: TOTALS | J1: =SUM(J4:J300) -> 0 | K1: =SUM(K4:K300) -> 0 | L1: =SUM(L4:L300) -> 0 | M1: =SUM(M4:M300) -> 0 | N1: =SUM(N4:N300) -> 0 | O1: =SUM(O4:O300) -> 0 | P1: =SUM(P4:P300) -> 0 | Q1: =SUM(Q4:Q300) -> 0 | ... U1: =SUM(U4:U300) -> 0 | V1: NOTES | W1: DO NOT EDIT THESE!!!
A2: Case # | B2: County | C2: Offense Date | D2: Disposition Date | E2: Adjudicated Charge Descriptions | F2: Adjudicated statutory reference (separate each individual code cite with a semicolon, no space) | G2: Disposition code | H2: Vehicular? | I2: Under supervison? | J2: INDIGENT DEFENSE | K2: COLLECTION COSTS | L2: JAIL / ROOM & BOARD | M2: SHERIFF FEES | N2: PROBATION FEES | O2: MISCELLANEOUS | P2: UNKNOWN | Q2: SURCHARGES | R2: FINES | S2: VICTIM RESTITUTION | T2: TOTAL
U3: ICOS TOTAL DUE (should be same as total)
T4: =SUM(J4:S4) -> 0 | W4: {=MID(";"&'CASE DATA'!$F4&";",SMALL(IF(ISERROR(SEARCH(MID(";"&'CASE DATA'!$F4&";",ROW($1:$99),1),";")),"",ROW($1:$99)+1),COLUMN(A4)),SMALL(IF(ISERROR(SEARCH(MID(";"&'CASE DATA'!$F4&";",ROW($1:$99),1),";")),"",ROW($1:$99)),COLUMN(A3)+1)-SMALL(IF(ISERROR(SEARCH(MID(";"&'CASE DATA'!$F4&";",ROW($1:$99),1),";")),"",ROW($1:$99)),COLUMN(A3))-1)} | X4: {=MID(";"&'CASE DATA'!$F4&";",SMALL(IF(ISERROR(SEARCH(MID(";"&'CASE DATA'!$F4&";",ROW($1:$99),1),";")),"",ROW($1:$99)+1),COLUMN(B4)),SMALL(IF(ISERROR(SEARCH(MID(";"&'CASE DATA'!$F4&";",ROW($1:$99),1),";")),"",ROW($1:$99)),COLUMN(B3)+1)-SMALL(IF(ISERROR(SEARCH(MID(";"&'CASE DATA'!$F4&";",ROW($1:$99),1),";")),"",ROW($1:$99)),COLUMN(B3))-1)} | Y4: {=MID(";"&'CASE DATA'!$F4&";",SMALL(IF(ISERROR(SEARCH(MID(";"&'CASE DATA'!$F4&";",ROW($1:$99),1),";")),"",ROW($1:$99)+1),COLUMN(C4)),SMALL(IF(ISERROR(SEARCH(MID(";"&'CASE DATA'!$F4&";",ROW($1:$99),1),";")),"",ROW($1:$99)),COLUMN(C3)+1)-SMALL(IF(ISERROR(SEARCH(MID(";"&'CASE DATA'!$F4&";",ROW($1:$99),1),";")),"",ROW($1:$99)),COLUMN(C3))-1)} | Z4: {=MID(";"&'CASE DATA'!$F4&";",SMALL(IF(ISERROR(SEARCH(MID(";"&'CASE DATA'!$F4&";",ROW($1:$99),1),";")),"",ROW($1:$99)+1),COLUMN(D4)),SMALL(IF(ISERROR(SEARCH(MID(";"&'CASE DATA'!$F4&";",ROW($1:$99),1),";")),"",ROW($1:$99)),COLUMN(D3)+1)-SMALL(IF(ISERROR(SEARCH(MID(";"&'CASE DATA'!$F4&";",ROW($1:$99),1),";")),"",ROW($1:$99)),COLUMN(D3))-1)} | AA4: {=MID(";"&'CASE DATA'!$F4&";",SMALL(IF(ISERROR(SEARCH(MID(";"&'CASE DATA'!$F4&";",ROW($1:$99),1),";")),"",ROW($1:$99)+1),COLUMN(E4)),SMALL(IF(ISERROR(SEARCH(MID(";"&'CASE DATA'!$F4&";",ROW($1:$99),1),";")),"",ROW($1:$99)),COLUMN(E3)+1)-SMALL(IF(ISERROR(SEARCH(MID(";"&'CASE DATA'!$F4&";",ROW($1:$99),1),";")),"",ROW($1:$99)),COLUMN(E3))-1)} | AB4: {=MID(";"&'CASE DATA'!$F4&";",SMALL(IF(ISERROR(SEARCH(MID(";"&'CASE DATA'!$F4&";",ROW($1:$99),1),";")),"",ROW($1:$99)+1),COLUMN(F4)),SMALL(IF(ISERROR(SEARCH(MID(";"&'CASE DATA'!$F4&";",ROW($1:$99),1),";")),"",ROW($1:$99)),COLUMN(F3)+1)-SMALL(IF(ISERROR(SEARCH(MID(";"&'CASE DATA'!$F4&";",ROW($1:$99),1),";")),"",ROW($1:$99)),COLUMN(F3))-1)} | AC4: {=MID(";"&'CASE DATA'!$F4&";",SMALL(IF(ISERROR(SEARCH(MID(";"&'CASE DATA'!$F4&";",ROW($1:$99),1),";")),"",ROW($1:$99)+1),COLUMN(G4)),SMALL(IF(ISERROR(SEARCH(MID(";"&'CASE DATA'!$F4&";",ROW($1:$99),1),";")),"",ROW($1:$99)),COLUMN(G3)+1)-SMALL(IF(ISERROR(SEARCH(MID(";"&'CASE DATA'!$F4&";",ROW($1:$99),1),";")),"",ROW($1:$99)),COLUMN(G3))-1)} | AD4: {=MID(";"&'CASE DATA'!$F4&";",SMALL(IF(ISERROR(SEARCH(MID(";"&'CASE DATA'!$F4&";",ROW($1:$99),1),";")),"",ROW($1:$99)+1),COLUMN(H4)),SMALL(IF(ISERROR(SEARCH(MID(";"&'CASE DATA'!$F4&";",ROW($1:$99),1),";")),"",ROW($1:$99)),COLUMN(H3)+1)-SMALL(IF(ISERROR(SEARCH(MID(";"&'CASE DATA'!$F4&";",ROW($1:$99),1),";")),"",ROW($1:$99)),COLUMN(H3))-1)} | ... AH4: {=MID(";"&'CASE DATA'!$F4&";",SMALL(IF(ISERROR(SEARCH(MID(";"&'CASE DATA'!$F4&";",ROW($1:$99),1),";")),"",ROW($1:$99)+1),COLUMN(L4)),SMALL(IF(ISERROR(SEARCH(MID(";"&'CASE DATA'!$F4&";",ROW($1:$99),1),";")),"",ROW($1:$99)),COLUMN(L3)+1)-SMALL(IF(ISERROR(SEARCH(MID(";"&'CASE DATA'!$F4&";",ROW($1:$99),1),";")),"",ROW($1:$99)),COLUMN(L3))-1)}
T5: =SUM(J5:S5) -> 0 | W5: {=MID(";"&'CASE DATA'!$F5&";",SMALL(IF(ISERROR(SEARCH(MID(";"&'CASE DATA'!$F5&";",ROW($1:$99),1),";")),"",ROW($1:$99)+1),COLUMN(A5)),SMALL(IF(ISERROR(SEARCH(MID(";"&'CASE DATA'!$F5&";",ROW($1:$99),1),";")),"",ROW($1:$99)),COLUMN(A4)+1)-SMALL(IF(ISERROR(SEARCH(MID(";"&'CASE DATA'!$F5&";",ROW($1:$99),1),";")),"",ROW($1:$99)),COLUMN(A4))-1)} | X5: {=MID(";"&'CASE DATA'!$F5&";",SMALL(IF(ISERROR(SEARCH(MID(";"&'CASE DATA'!$F5&";",ROW($1:$99),1),";")),"",ROW($1:$99)+1),COLUMN(B5)),SMALL(IF(ISERROR(SEARCH(MID(";"&'CASE DATA'!$F5&";",ROW($1:$99),1),";")),"",ROW($1:$99)),COLUMN(B4)+1)-SMALL(IF(ISERROR(SEARCH(MID(";"&'CASE DATA'!$F5&";",ROW($1:$99),1),";")),"",ROW($1:$99)),COLUMN(B4))-1)} | Y5: {=MID(";"&'CASE DATA'!$F5&";",SMALL(IF(ISERROR(SEARCH(MID(";"&'CASE DATA'!$F5&";",ROW($1:$99),1),";")),"",ROW($1:$99)+1),COLUMN(D5)),SMALL(IF(ISERROR(SEARCH(MID(";"&'CASE DATA'!$F5&";",ROW($1:$99),1),";")),"",ROW($1:$99)),COLUMN(D4)+1)-SMALL(IF(ISERROR(SEARCH(MID(";"&'CASE DATA'!$F5&";",ROW($1:$99),1),";")),"",ROW($1:$99)),COLUMN(D4))-1)} | Z5: {=MID(";"&'CASE DATA'!$F5&";",SMALL(IF(ISERROR(SEARCH(MID(";"&'CASE DATA'!$F5&";",ROW($1:$99),1),";")),"",ROW($1:$99)+1),COLUMN(E5)),SMALL(IF(ISERROR(SEARCH(MID(";"&'CASE DATA'!$F5&";",ROW($1:$99),1),";")),"",ROW($1:$99)),COLUMN(E4)+1)-SMALL(IF(ISERROR(SEARCH(MID(";"&'CASE DATA'!$F5&";",ROW($1:$99),1),";")),"",ROW($1:$99)),COLUMN(E4))-1)} | AA5: {=MID(";"&'CASE DATA'!$F5&";",SMALL(IF(ISERROR(SEARCH(MID(";"&'CASE DATA'!$F5&";",ROW($1:$99),1),";")),"",ROW($1:$99)+1),COLUMN(F5)),SMALL(IF(ISERROR(SEARCH(MID(";"&'CASE DATA'!$F5&";",ROW($1:$99),1),";")),"",ROW($1:$99)),COLUMN(F4)+1)-SMALL(IF(ISERROR(SEARCH(MID(";"&'CASE DATA'!$F5&";",ROW($1:$99),1),";")),"",ROW($1:$99)),COLUMN(F4))-1)} | AB5: {=MID(";"&'CASE DATA'!$F5&";",SMALL(IF(ISERROR(SEARCH(MID(";"&'CASE DATA'!$F5&";",ROW($1:$99),1),";")),"",ROW($1:$99)+1),COLUMN(G5)),SMALL(IF(ISERROR(SEARCH(MID(";"&'CASE DATA'!$F5&";",ROW($1:$99),1),";")),"",ROW($1:$99)),COLUMN(G4)+1)-SMALL(IF(ISERROR(SEARCH(MID(";"&'CASE DATA'!$F5&";",ROW($1:$99),1),";")),"",ROW($1:$99)),COLUMN(G4))-1)} | AC5: {=MID(";"&'CASE DATA'!$F5&";",SMALL(IF(ISERROR(SEARCH(MID(";"&'CASE DATA'!$F5&";",ROW($1:$99),1),";")),"",ROW($1:$99)+1),COLUMN(H5)),SMALL(IF(ISERROR(SEARCH(MID(";"&'CASE DATA'!$F5&";",ROW($1:$99),1),";")),"",ROW($1:$99)),COLUMN(H4)+1)-SMALL(IF(ISERROR(SEARCH(MID(";"&'CASE DATA'!$F5&";",ROW($1:$99),1),";")),"",ROW($1:$99)),COLUMN(H4))-1)} | AD5: {=MID(";"&'CASE DATA'!$F5&";",SMALL(IF(ISERROR(SEARCH(MID(";"&'CASE DATA'!$F5&";",ROW($1:$99),1),";")),"",ROW($1:$99)+1),COLUMN(I5)),SMALL(IF(ISERROR(SEARCH(MID(";"&'CASE DATA'!$F5&";",ROW($1:$99),1),";")),"",ROW($1:$99)),COLUMN(I4)+1)-SMALL(IF(ISERROR(SEARCH(MID(";"&'CASE DATA'!$F5&";",ROW($1:$99),1),";")),"",ROW($1:$99)),COLUMN(I4))-1)} | AE5: {=MID(";"&'CASE DATA'!$F5&";",SMALL(IF(ISERROR(SEARCH(MID(";"&'CASE DATA'!$F5&";",ROW($1:$99),1),";")),"",ROW($1:$99)+1),COLUMN(J5)),SMALL(IF(ISERROR(SEARCH(MID(";"&'CASE DATA'!$F5&";",ROW($1:$99),1),";")),"",ROW($1:$99)),COLUMN(J4)+1)-SMALL(IF(ISERROR(SEARCH(MID(";"&'CASE DATA'!$F5&";",ROW($1:$99),1),";")),"",ROW($1:$99)),COLUMN(J4))-1)} | AF5: {=MID(";"&'CASE DATA'!$F5&";",SMALL(IF(ISERROR(SEARCH(MID(";"&'CASE DATA'!$F5&";",ROW($1:$99),1),";")),"",ROW($1:$99)+1),COLUMN(K5)),SMALL(IF(ISERROR(SEARCH(MID(";"&'CASE DATA'!$F5&";",ROW($1:$99),1),";")),"",ROW($1:$99)),COLUMN(K3)+1)-SMALL(IF(ISERROR(SEARCH(MID(";"&'CASE DATA'!$F5&";",ROW($1:$99),1),";")),"",ROW($1:$99)),COLUMN(K3))-1)} | AG5: {=MID(";"&'CASE DATA'!$F5&";",SMALL(IF(ISERROR(SEARCH(MID(";"&'CASE DATA'!$F5&";",ROW($1:$99),1),";")),"",ROW($1:$99)+1),COLUMN(L5)),SMALL(IF(ISERROR(SEARCH(MID(";"&'CASE DATA'!$F5&";",ROW($1:$99),1),";")),"",ROW($1:$99)),COLUMN(L3)+1)-SMALL(IF(ISERROR(SEARCH(MID(";"&'CASE DATA'!$F5&";",ROW($1:$99),1),";")),"",ROW($1:$99)),COLUMN(L3))-1)} | AH5: {=MID(";"&'CASE DATA'!$F5&";",SMALL(IF(ISERROR(SEARCH(MID(";"&'CASE DATA'!$F5&";",ROW($1:$99),1),";")),"",ROW($1:$99)+1),COLUMN(M5)),SMALL(IF(ISERROR(SEARCH(MID(";"&'CASE DATA'!$F5&";",ROW($1:$99),1),";")),"",ROW($1:$99)),COLUMN(M3)+1)-SMALL(IF(ISERROR(SEARCH(MID(";"&'CASE DATA'!$F5&";",ROW($1:$99),1),";")),"",ROW($1:$99)),COLUMN(M3))-1)}
T6: =SUM(J6:S6) -> 0 | W6: {=MID(";"&'CASE DATA'!$F6&";",SMALL(IF(ISERROR(SEARCH(MID(";"&'CASE DATA'!$F6&";",ROW($1:$99),1),";")),"",ROW($1:$99)+1),COLUMN(A6)),SMALL(IF(ISERROR(SEARCH(MID(";"&'CASE DATA'!$F6&";",ROW($1:$99),1),";")),"",ROW($1:$99)),COLUMN(A5)+1)-SMALL(IF(ISERROR(SEARCH(MID(";"&'CASE DATA'!$F6&";",ROW($1:$99),1),";")),"",ROW($1:$99)),COLUMN(A5))-1)} | X6: {=MID(";"&'CASE DATA'!$F6&";",SMALL(IF(ISERROR(SEARCH(MID(";"&'CASE DATA'!$F6&";",ROW($1:$99),1),";")),"",ROW($1:$99)+1),COLUMN(B6)),SMALL(IF(ISERROR(SEARCH(MID(";"&'CASE DATA'!$F6&";",ROW($1:$99),1),";")),"",ROW($1:$99)),COLUMN(B5)+1)-SMALL(IF(ISERROR(SEARCH(MID(";"&'CASE DATA'!$F6&";",ROW($1:$99),1),";")),"",ROW($1:$99)),COLUMN(B5))-1)} | Y6: {=MID(";"&'CASE DATA'!$F6&";",SMALL(IF(ISERROR(SEARCH(MID(";"&'CASE DATA'!$F6&";",ROW($1:$99),1),";")),"",ROW($1:$99)+1),COLUMN(C6)),SMALL(IF(ISERROR(SEARCH(MID(";"&'CASE DATA'!$F6&";",ROW($1:$99),1),";")),"",ROW($1:$99)),COLUMN(C5)+1)-SMALL(IF(ISERROR(SEARCH(MID(";"&'CASE DATA'!$F6&";",ROW($1:$99),1),";")),"",ROW($1:$99)),COLUMN(C5))-1)} | Z6: {=MID(";"&'CASE DATA'!$F6&";",SMALL(IF(ISERROR(SEARCH(MID(";"&'CASE DATA'!$F6&";",ROW($1:$99),1),";")),"",ROW($1:$99)+1),COLUMN(D6)),SMALL(IF(ISERROR(SEARCH(MID(";"&'CASE DATA'!$F6&";",ROW($1:$99),1),";")),"",ROW($1:$99)),COLUMN(D5)+1)-SMALL(IF(ISERROR(SEARCH(MID(";"&'CASE DATA'!$F6&";",ROW($1:$99),1),";")),"",ROW($1:$99)),COLUMN(D5))-1)} | AA6: {=MID(";"&'CASE DATA'!$F6&";",SMALL(IF(ISERROR(SEARCH(MID(";"&'CASE DATA'!$F6&";",ROW($1:$99),1),";")),"",ROW($1:$99)+1),COLUMN(E6)),SMALL(IF(ISERROR(SEARCH(MID(";"&'CASE DATA'!$F6&";",ROW($1:$99),1),";")),"",ROW($1:$99)),COLUMN(E5)+1)-SMALL(IF(ISERROR(SEARCH(MID(";"&'CASE DATA'!$F6&";",ROW($1:$99),1),";")),"",ROW($1:$99)),COLUMN(E5))-1)} | AB6: {=MID(";"&'CASE DATA'!$F6&";",SMALL(IF(ISERROR(SEARCH(MID(";"&'CASE DATA'!$F6&";",ROW($1:$99),1),";")),"",ROW($1:$99)+1),COLUMN(F6)),SMALL(IF(ISERROR(SEARCH(MID(";"&'CASE DATA'!$F6&";",ROW($1:$99),1),";")),"",ROW($1:$99)),COLUMN(F5)+1)-SMALL(IF(ISERROR(SEARCH(MID(";"&'CASE DATA'!$F6&";",ROW($1:$99),1),";")),"",ROW($1:$99)),COLUMN(F5))-1)} | AC6: {=MID(";"&'CASE DATA'!$F6&";",SMALL(IF(ISERROR(SEARCH(MID(";"&'CASE DATA'!$F6&";",ROW($1:$99),1),";")),"",ROW($1:$99)+1),COLUMN(G6)),SMALL(IF(ISERROR(SEARCH(MID(";"&'CASE DATA'!$F6&";",ROW($1:$99),1),";")),"",ROW($1:$99)),COLUMN(G5)+1)-SMALL(IF(ISERROR(SEARCH(MID(";"&'CASE DATA'!$F6&";",ROW($1:$99),1),";")),"",ROW($1:$99)),COLUMN(G5))-1)} | AD6: {=MID(";"&'CASE DATA'!$F6&";",SMALL(IF(ISERROR(SEARCH(MID(";"&'CASE DATA'!$F6&";",ROW($1:$99),1),";")),"",ROW($1:$99)+1),COLUMN(H6)),SMALL(IF(ISERROR(SEARCH(MID(";"&'CASE DATA'!$F6&";",ROW($1:$99),1),";")),"",ROW($1:$99)),COLUMN(H5)+1)-SMALL(IF(ISERROR(SEARCH(MID(";"&'CASE DATA'!$F6&";",ROW($1:$99),1),";")),"",ROW($1:$99)),COLUMN(H5))-1)} | ... AH6: {=MID(";"&'CASE DATA'!$F6&";",SMALL(IF(ISERROR(SEARCH(MID(";"&'CASE DATA'!$F6&";",ROW($1:$99),1),";")),"",ROW($1:$99)+1),COLUMN(L6)),SMALL(IF(ISERROR(SEARCH(MID(";"&'CASE DATA'!$F6&";",ROW($1:$99),1),";")),"",ROW($1:$99)),COLUMN(L5)+1)-SMALL(IF(ISERROR(SEARCH(MID(";"&'CASE DATA'!$F6&";",ROW($1:$99),1),";")),"",ROW($1:$99)),COLUMN(L5))-1)}
T7: =SUM(J7:S7) -> 0 | W7: {=MID(";"&'CASE DATA'!$F7&";",SMALL(IF(ISERROR(SEARCH(MID(";"&'CASE DATA'!$F7&";",ROW($1:$99),1),";")),"",ROW($1:$99)+1),COLUMN(A7)),SMALL(IF(ISERROR(SEARCH(MID(";"&'CASE DATA'!$F7&";",ROW($1:$99),1),";")),"",ROW($1:$99)),COLUMN(A6)+1)-SMALL(IF(ISERROR(SEARCH(MID(";"&'CASE DATA'!$F7&";",ROW($1:$99),1),";")),"",ROW($1:$99)),COLUMN(A6))-1)} | X7: {=MID(";"&'CASE DATA'!$F7&";",SMALL(IF(ISERROR(SEARCH(MID(";"&'CASE DATA'!$F7&";",ROW($1:$99),1),";")),"",ROW($1:$99)+1),COLUMN(B7)),SMALL(IF(ISERROR(SEARCH(MID(";"&'CASE DATA'!$F7&";",ROW($1:$99),1),";")),"",ROW($1:$99)),COLUMN(B6)+1)-SMALL(IF(ISERROR(SEARCH(MID(";"&'CASE DATA'!$F7&";",ROW($1:$99),1),";")),"",ROW($1:$99)),COLUMN(B6))-1)} | Y7: {=MID(";"&'CASE DATA'!$F7&";",SMALL(IF(ISERROR(SEARCH(MID(";"&'CASE DATA'!$F7&";",ROW($1:$99),1),";")),"",ROW($1:$99)+1),COLUMN(D7)),SMALL(IF(ISERROR(SEARCH(MID(";"&'CASE DATA'!$F7&";",ROW($1:$99),1),";")),"",ROW($1:$99)),COLUMN(D6)+1)-SMALL(IF(ISERROR(SEARCH(MID(";"&'CASE DATA'!$F7&";",ROW($1:$99),1),";")),"",ROW($1:$99)),COLUMN(D6))-1)} | Z7: {=MID(";"&'CASE DATA'!$F7&";",SMALL(IF(ISERROR(SEARCH(MID(";"&'CASE DATA'!$F7&";",ROW($1:$99),1),";")),"",ROW($1:$99)+1),COLUMN(E7)),SMALL(IF(ISERROR(SEARCH(MID(";"&'CASE DATA'!$F7&";",ROW($1:$99),1),";")),"",ROW($1:$99)),COLUMN(E6)+1)-SMALL(IF(ISERROR(SEARCH(MID(";"&'CASE DATA'!$F7&";",ROW($1:$99),1),";")),"",ROW($1:$99)),COLUMN(E6))-1)} | AA7: {=MID(";"&'CASE DATA'!$F7&";",SMALL(IF(ISERROR(SEARCH(MID(";"&'CASE DATA'!$F7&";",ROW($1:$99),1),";")),"",ROW($1:$99)+1),COLUMN(F7)),SMALL(IF(ISERROR(SEARCH(MID(";"&'CASE DATA'!$F7&";",ROW($1:$99),1),";")),"",ROW($1:$99)),COLUMN(F6)+1)-SMALL(IF(ISERROR(SEARCH(MID(";"&'CASE DATA'!$F7&";",ROW($1:$99),1),";")),"",ROW($1:$99)),COLUMN(F6))-1)} | AB7: {=MID(";"&'CASE DATA'!$F7&";",SMALL(IF(ISERROR(SEARCH(MID(";"&'CASE DATA'!$F7&";",ROW($1:$99),1),";")),"",ROW($1:$99)+1),COLUMN(G7)),SMALL(IF(ISERROR(SEARCH(MID(";"&'CASE DATA'!$F7&";",ROW($1:$99),1),";")),"",ROW($1:$99)),COLUMN(G6)+1)-SMALL(IF(ISERROR(SEARCH(MID(";"&'CASE DATA'!$F7&";",ROW($1:$99),1),";")),"",ROW($1:$99)),COLUMN(G6))-1)} | AC7: {=MID(";"&'CASE DATA'!$F7&";",SMALL(IF(ISERROR(SEARCH(MID(";"&'CASE DATA'!$F7&";",ROW($1:$99),1),";")),"",ROW($1:$99)+1),COLUMN(H7)),SMALL(IF(ISERROR(SEARCH(MID(";"&'CASE DATA'!$F7&";",ROW($1:$99),1),";")),"",ROW($1:$99)),COLUMN(H6)+1)-SMALL(IF(ISERROR(SEARCH(MID(";"&'CASE DATA'!$F7&";",ROW($1:$99),1),";")),"",ROW($1:$99)),COLUMN(H6))-1)} | AD7: {=MID(";"&'CASE DATA'!$F7&";",SMALL(IF(ISERROR(SEARCH(MID(";"&'CASE DATA'!$F7&";",ROW($1:$99),1),";")),"",ROW($1:$99)+1),COLUMN(I7)),SMALL(IF(ISERROR(SEARCH(MID(";"&'CASE DATA'!$F7&";",ROW($1:$99),1),";")),"",ROW($1:$99)),COLUMN(I6)+1)-SMALL(IF(ISERROR(SEARCH(MID(";"&'CASE DATA'!$F7&";",ROW($1:$99),1),";")),"",ROW($1:$99)),COLUMN(I6))-1)} | AE7: {=MID(";"&'CASE DATA'!$F7&";",SMALL(IF(ISERROR(SEARCH(MID(";"&'CASE DATA'!$F7&";",ROW($1:$99),1),";")),"",ROW($1:$99)+1),COLUMN(J7)),SMALL(IF(ISERROR(SEARCH(MID(";"&'CASE DATA'!$F7&";",ROW($1:$99),1),";")),"",ROW($1:$99)),COLUMN(J6)+1)-SMALL(IF(ISERROR(SEARCH(MID(";"&'CASE DATA'!$F7&";",ROW($1:$99),1),";")),"",ROW($1:$99)),COLUMN(J6))-1)} | AF7: {=MID(";"&'CASE DATA'!$F7&";",SMALL(IF(ISERROR(SEARCH(MID(";"&'CASE DATA'!$F7&";",ROW($1:$99),1),";")),"",ROW($1:$99)+1),COLUMN(K7)),SMALL(IF(ISERROR(SEARCH(MID(";"&'CASE DATA'!$F7&";",ROW($1:$99),1),";")),"",ROW($1:$99)),COLUMN(K6)+1)-SMALL(IF(ISERROR(SEARCH(MID(";"&'CASE DATA'!$F7&";",ROW($1:$99),1),";")),"",ROW($1:$99)),COLUMN(K6))-1)} | ... AH7: {=MID(";"&'CASE DATA'!$F7&";",SMALL(IF(ISERROR(SEARCH(MID(";"&'CASE DATA'!$F7&";",ROW($1:$99),1),";")),"",ROW($1:$99)+1),COLUMN(M7)),SMALL(IF(ISERROR(SEARCH(MID(";"&'CASE DATA'!$F7&";",ROW($1:$99),1),";")),"",ROW($1:$99)),COLUMN(M6)+1)-SMALL(IF(ISERROR(SEARCH(MID(";"&'CASE DATA'!$F7&";",ROW($1:$99),1),";")),"",ROW($1:$99)),COLUMN(M6))-1)}
T8: =SUM(J8:S8) -> 0 | W8: {=MID(";"&'CASE DATA'!$F8&";",SMALL(IF(ISERROR(SEARCH(MID(";"&'CASE DATA'!$F8&";",ROW($1:$99),1),";")),"",ROW($1:$99)+1),COLUMN(A8)),SMALL(IF(ISERROR(SEARCH(MID(";"&'CASE DATA'!$F8&";",ROW($1:$99),1),";")),"",ROW($1:$99)),COLUMN(A7)+1)-SMALL(IF(ISERROR(SEARCH(MID(";"&'CASE DATA'!$F8&";",ROW($1:$99),1),";")),"",ROW($1:$99)),COLUMN(A7))-1)} | X8: {=MID(";"&'CASE DATA'!$F8&";",SMALL(IF(ISERROR(SEARCH(MID(";"&'CASE DATA'!$F8&";",ROW($1:$99),1),";")),"",ROW($1:$99)+1),COLUMN(B8)),SMALL(IF(ISERROR(SEARCH(MID(";"&'CASE DATA'!$F8&";",ROW($1:$99),1),";")),"",ROW($1:$99)),COLUMN(B7)+1)-SMALL(IF(ISERROR(SEARCH(MID(";"&'CASE DATA'!$F8&";",ROW($1:$99),1),";")),"",ROW($1:$99)),COLUMN(B7))-1)} | Y8: {=MID(";"&'CASE DATA'!$F8&";",SMALL(IF(ISERROR(SEARCH(MID(";"&'CASE DATA'!$F8&";",ROW($1:$99),1),";")),"",ROW($1:$99)+1),COLUMN(D8)),SMALL(IF(ISERROR(SEARCH(MID(";"&'CASE DATA'!$F8&";",ROW($1:$99),1),";")),"",ROW($1:$99)),COLUMN(D7)+1)-SMALL(IF(ISERROR(SEARCH(MID(";"&'CASE DATA'!$F8&";",ROW($1:$99),1),";")),"",ROW($1:$99)),COLUMN(D7))-1)} | Z8: {=MID(";"&'CASE DATA'!$F8&";",SMALL(IF(ISERROR(SEARCH(MID(";"&'CASE DATA'!$F8&";",ROW($1:$99),1),";")),"",ROW($1:$99)+1),COLUMN(E8)),SMALL(IF(ISERROR(SEARCH(MID(";"&'CASE DATA'!$F8&";",ROW($1:$99),1),";")),"",ROW($1:$99)),COLUMN(E7)+1)-SMALL(IF(ISERROR(SEARCH(MID(";"&'CASE DATA'!$F8&";",ROW($1:$99),1),";")),"",ROW($1:$99)),COLUMN(E7))-1)} | AA8: {=MID(";"&'CASE DATA'!$F8&";",SMALL(IF(ISERROR(SEARCH(MID(";"&'CASE DATA'!$F8&";",ROW($1:$99),1),";")),"",ROW($1:$99)+1),COLUMN(F8)),SMALL(IF(ISERROR(SEARCH(MID(";"&'CASE DATA'!$F8&";",ROW($1:$99),1),";")),"",ROW($1:$99)),COLUMN(F7)+1)-SMALL(IF(ISERROR(SEARCH(MID(";"&'CASE DATA'!$F8&";",ROW($1:$99),1),";")),"",ROW($1:$99)),COLUMN(F7))-1)} | AB8: {=MID(";"&'CASE DATA'!$F8&";",SMALL(IF(ISERROR(SEARCH(MID(";"&'CASE DATA'!$F8&";",ROW($1:$99),1),";")),"",ROW($1:$99)+1),COLUMN(G8)),SMALL(IF(ISERROR(SEARCH(MID(";"&'CASE DATA'!$F8&";",ROW($1:$99),1),";")),"",ROW($1:$99)),COLUMN(G7)+1)-SMALL(IF(ISERROR(SEARCH(MID(";"&'CASE DATA'!$F8&";",ROW($1:$99),1),";")),"",ROW($1:$99)),COLUMN(G7))-1)} | AC8: {=MID(";"&'CASE DATA'!$F8&";",SMALL(IF(ISERROR(SEARCH(MID(";"&'CASE DATA'!$F8&";",ROW($1:$99),1),";")),"",ROW($1:$99)+1),COLUMN(H8)),SMALL(IF(ISERROR(SEARCH(MID(";"&'CASE DATA'!$F8&";",ROW($1:$99),1),";")),"",ROW($1:$99)),COLUMN(H7)+1)-SMALL(IF(ISERROR(SEARCH(MID(";"&'CASE DATA'!$F8&";",ROW($1:$99),1),";")),"",ROW($1:$99)),COLUMN(H7))-1)} | AD8: {=MID(";"&'CASE DATA'!$F8&";",SMALL(IF(ISERROR(SEARCH(MID(";"&'CASE DATA'!$F8&";",ROW($1:$99),1),";")),"",ROW($1:$99)+1),COLUMN(I8)),SMALL(IF(ISERROR(SEARCH(MID(";"&'CASE DATA'!$F8&";",ROW($1:$99),1),";")),"",ROW($1:$99)),COLUMN(I7)+1)-SMALL(IF(ISERROR(SEARCH(MID(";"&'CASE DATA'!$F8&";",ROW($1:$99),1),";")),"",ROW($1:$99)),COLUMN(I7))-1)} | AE8: {=MID(";"&'CASE DATA'!$F8&";",SMALL(IF(ISERROR(SEARCH(MID(";"&'CASE DATA'!$F8&";",ROW($1:$99),1),";")),"",ROW($1:$99)+1),COLUMN(J8)),SMALL(IF(ISERROR(SEARCH(MID(";"&'CASE DATA'!$F8&";",ROW($1:$99),1),";")),"",ROW($1:$99)),COLUMN(J7)+1)-SMALL(IF(ISERROR(SEARCH(MID(";"&'CASE DATA'!$F8&";",ROW($1:$99),1),";")),"",ROW($1:$99)),COLUMN(J7))-1)} | AF8: {=MID(";"&'CASE DATA'!$F8&";",SMALL(IF(ISERROR(SEARCH(MID(";"&'CASE DATA'!$F8&";",ROW($1:$99),1),";")),"",ROW($1:$99)+1),COLUMN(K8)),SMALL(IF(ISERROR(SEARCH(MID(";"&'CASE DATA'!$F8&";",ROW($1:$99),1),";")),"",ROW($1:$99)),COLUMN(K7)+1)-SMALL(IF(ISERROR(SEARCH(MID(";"&'CASE DATA'!$F8&";",ROW($1:$99),1),";")),"",ROW($1:$99)),COLUMN(K7))-1)} | ... AH8: {=MID(";"&'CASE DATA'!$F8&";",SMALL(IF(ISERROR(SEARCH(MID(";"&'CASE DATA'!$F8&";",ROW($1:$99),1),";")),"",ROW($1:$99)+1),COLUMN(M8)),SMALL(IF(ISERROR(SEARCH(MID(";"&'CASE DATA'!$F8&";",ROW($1:$99),1),";")),"",ROW($1:$99)),COLUMN(M7)+1)-SMALL(IF(ISERROR(SEARCH(MID(";"&'CASE DATA'!$F8&";",ROW($1:$99),1),";")),"",ROW($1:$99)),COLUMN(M7))-1)}
T9: =SUM(J9:S9) -> 0 | W9: {=MID(";"&'CASE DATA'!$F9&";",SMALL(IF(ISERROR(SEARCH(MID(";"&'CASE DATA'!$F9&";",ROW($1:$99),1),";")),"",ROW($1:$99)+1),COLUMN(A9)),SMALL(IF(ISERROR(SEARCH(MID(";"&'CASE DATA'!$F9&";",ROW($1:$99),1),";")),"",ROW($1:$99)),COLUMN(A8)+1)-SMALL(IF(ISERROR(SEARCH(MID(";"&'CASE DATA'!$F9&";",ROW($1:$99),1),";")),"",ROW($1:$99)),COLUMN(A8))-1)} | X9: {=MID(";"&'CASE DATA'!$F9&";",SMALL(IF(ISERROR(SEARCH(MID(";"&'CASE DATA'!$F9&";",ROW($1:$99),1),";")),"",ROW($1:$99)+1),COLUMN(B9)),SMALL(IF(ISERROR(SEARCH(MID(";"&'CASE DATA'!$F9&";",ROW($1:$99),1),";")),"",ROW($1:$99)),COLUMN(B8)+1)-SMALL(IF(ISERROR(SEARCH(MID(";"&'CASE DATA'!$F9&";",ROW($1:$99),1),";")),"",ROW($1:$99)),COLUMN(B8))-1)} | Y9: {=MID(";"&'CASE DATA'!$F9&";",SMALL(IF(ISERROR(SEARCH(MID(";"&'CASE DATA'!$F9&";",ROW($1:$99),1),";")),"",ROW($1:$99)+1),COLUMN(D9)),SMALL(IF(ISERROR(SEARCH(MID(";"&'CASE DATA'!$F9&";",ROW($1:$99),1),";")),"",ROW($1:$99)),COLUMN(D8)+1)-SMALL(IF(ISERROR(SEARCH(MID(";"&'CASE DATA'!$F9&";",ROW($1:$99),1),";")),"",ROW($1:$99)),COLUMN(D8))-1)} | Z9: {=MID(";"&'CASE DATA'!$F9&";",SMALL(IF(ISERROR(SEARCH(MID(";"&'CASE DATA'!$F9&";",ROW($1:$99),1),";")),"",ROW($1:$99)+1),COLUMN(E9)),SMALL(IF(ISERROR(SEARCH(MID(";"&'CASE DATA'!$F9&";",ROW($1:$99),1),";")),"",ROW($1:$99)),COLUMN(E8)+1)-SMALL(IF(ISERROR(SEARCH(MID(";"&'CASE DATA'!$F9&";",ROW($1:$99),1),";")),"",ROW($1:$99)),COLUMN(E8))-1)} | AA9: {=MID(";"&'CASE DATA'!$F9&";",SMALL(IF(ISERROR(SEARCH(MID(";"&'CASE DATA'!$F9&";",ROW($1:$99),1),";")),"",ROW($1:$99)+1),COLUMN(F9)),SMALL(IF(ISERROR(SEARCH(MID(";"&'CASE DATA'!$F9&";",ROW($1:$99),1),";")),"",ROW($1:$99)),COLUMN(F8)+1)-SMALL(IF(ISERROR(SEARCH(MID(";"&'CASE DATA'!$F9&";",ROW($1:$99),1),";")),"",ROW($1:$99)),COLUMN(F8))-1)} | AB9: {=MID(";"&'CASE DATA'!$F9&";",SMALL(IF(ISERROR(SEARCH(MID(";"&'CASE DATA'!$F9&";",ROW($1:$99),1),";")),"",ROW($1:$99)+1),COLUMN(G9)),SMALL(IF(ISERROR(SEARCH(MID(";"&'CASE DATA'!$F9&";",ROW($1:$99),1),";")),"",ROW($1:$99)),COLUMN(G8)+1)-SMALL(IF(ISERROR(SEARCH(MID(";"&'CASE DATA'!$F9&";",ROW($1:$99),1),";")),"",ROW($1:$99)),COLUMN(G8))-1)} | AC9: {=MID(";"&'CASE DATA'!$F9&";",SMALL(IF(ISERROR(SEARCH(MID(";"&'CASE DATA'!$F9&";",ROW($1:$99),1),";")),"",ROW($1:$99)+1),COLUMN(H9)),SMALL(IF(ISERROR(SEARCH(MID(";"&'CASE DATA'!$F9&";",ROW($1:$99),1),";")),"",ROW($1:$99)),COLUMN(H8)+1)-SMALL(IF(ISERROR(SEARCH(MID(";"&'CASE DATA'!$F9&";",ROW($1:$99),1),";")),"",ROW($1:$99)),COLUMN(H8))-1)} | AD9: {=MID(";"&'CASE DATA'!$F9&";",SMALL(IF(ISERROR(SEARCH(MID(";"&'CASE DATA'!$F9&";",ROW($1:$99),1),";")),"",ROW($1:$99)+1),COLUMN(I9)),SMALL(IF(ISERROR(SEARCH(MID(";"&'CASE DATA'!$F9&";",ROW($1:$99),1),";")),"",ROW($1:$99)),COLUMN(I8)+1)-SMALL(IF(ISERROR(SEARCH(MID(";"&'CASE DATA'!$F9&";",ROW($1:$99),1),";")),"",ROW($1:$99)),COLUMN(I8))-1)} | AE9: {=MID(";"&'CASE DATA'!$F9&";",SMALL(IF(ISERROR(SEARCH(MID(";"&'CASE DATA'!$F9&";",ROW($1:$99),1),";")),"",ROW($1:$99)+1),COLUMN(J9)),SMALL(IF(ISERROR(SEARCH(MID(";"&'CASE DATA'!$F9&";",ROW($1:$99),1),";")),"",ROW($1:$99)),COLUMN(J8)+1)-SMALL(IF(ISERROR(SEARCH(MID(";"&'CASE DATA'!$F9&";",ROW($1:$99),1),";")),"",ROW($1:$99)),COLUMN(J8))-1)} | AF9: {=MID(";"&'CASE DATA'!$F9&";",SMALL(IF(ISERROR(SEARCH(MID(";"&'CASE DATA'!$F9&";",ROW($1:$99),1),";")),"",ROW($1:$99)+1),COLUMN(K9)),SMALL(IF(ISERROR(SEARCH(MID(";"&'CASE DATA'!$F9&";",ROW($1:$99),1),";")),"",ROW($1:$99)),COLUMN(K8)+1)-SMALL(IF(ISERROR(SEARCH(MID(";"&'CASE DATA'!$F9&";",ROW($1:$99),1),";")),"",ROW($1:$99)),COLUMN(K8))-1)} | ... AI9: {=MID(";"&'CASE DATA'!$F9&";",SMALL(IF(ISERROR(SEARCH(MID(";"&'CASE DATA'!$F9&";",ROW($1:$99),1),";")),"",ROW($1:$99)+1),COLUMN(N9)),SMALL(IF(ISERROR(SEARCH(MID(";"&'CASE DATA'!$F9&";",ROW($1:$99),1),";")),"",ROW($1:$99)),COLUMN(N8)+1)-SMALL(IF(ISERROR(SEARCH(MID(";"&'CASE DATA'!$F9&";",ROW($1:$99),1),";")),"",ROW($1:$99)),COLUMN(N8))-1)}
T10: =SUM(J10:S10) -> 0 | W10: {=MID(";"&'CASE DATA'!$F10&";",SMALL(IF(ISERROR(SEARCH(MID(";"&'CASE DATA'!$F10&";",ROW($1:$99),1),";")),"",ROW($1:$99)+1),COLUMN(A10)),SMALL(IF(ISERROR(SEARCH(MID(";"&'CASE DATA'!$F10&";",ROW($1:$99),1),";")),"",ROW($1:$99)),COLUMN(A9)+1)-SMALL(IF(ISERROR(SEARCH(MID(";"&'CASE DATA'!$F10&";",ROW($1:$99),1),";")),"",ROW($1:$99)),COLUMN(A9))-1)} | X10: {=MID(";"&'CASE DATA'!$F10&";",SMALL(IF(ISERROR(SEARCH(MID(";"&'CASE DATA'!$F10&";",ROW($1:$99),1),";")),"",ROW($1:$99)+1),COLUMN(B10)),SMALL(IF(ISERROR(SEARCH(MID(";"&'CASE DATA'!$F10&";",ROW($1:$99),1),";")),"",ROW($1:$99)),COLUMN(B9)+1)-SMALL(IF(ISERROR(SEARCH(MID(";"&'CASE DATA'!$F10&";",ROW($1:$99),1),";")),"",ROW($1:$99)),COLUMN(B9))-1)} | Y10: {=MID(";"&'CASE DATA'!$F10&";",SMALL(IF(ISERROR(SEARCH(MID(";"&'CASE DATA'!$F10&";",ROW($1:$99),1),";")),"",ROW($1:$99)+1),COLUMN(D10)),SMALL(IF(ISERROR(SEARCH(MID(";"&'CASE DATA'!$F10&";",ROW($1:$99),1),";")),"",ROW($1:$99)),COLUMN(D9)+1)-SMALL(IF(ISERROR(SEARCH(MID(";"&'CASE DATA'!$F10&";",ROW($1:$99),1),";")),"",ROW($1:$99)),COLUMN(D9))-1)} | Z10: {=MID(";"&'CASE DATA'!$F10&";",SMALL(IF(ISERROR(SEARCH(MID(";"&'CASE DATA'!$F10&";",ROW($1:$99),1),";")),"",ROW($1:$99)+1),COLUMN(E10)),SMALL(IF(ISERROR(SEARCH(MID(";"&'CASE DATA'!$F10&";",ROW($1:$99),1),";")),"",ROW($1:$99)),COLUMN(E9)+1)-SMALL(IF(ISERROR(SEARCH(MID(";"&'CASE DATA'!$F10&";",ROW($1:$99),1),";")),"",ROW($1:$99)),COLUMN(E9))-1)} | AA10: {=MID(";"&'CASE DATA'!$F10&";",SMALL(IF(ISERROR(SEARCH(MID(";"&'CASE DATA'!$F10&";",ROW($1:$99),1),";")),"",ROW($1:$99)+1),COLUMN(F10)),SMALL(IF(ISERROR(SEARCH(MID(";"&'CASE DATA'!$F10&";",ROW($1:$99),1),";")),"",ROW($1:$99)),COLUMN(F9)+1)-SMALL(IF(ISERROR(SEARCH(MID(";"&'CASE DATA'!$F10&";",ROW($1:$99),1),";")),"",ROW($1:$99)),COLUMN(F9))-1)} | AB10: {=MID(";"&'CASE DATA'!$F10&";",SMALL(IF(ISERROR(SEARCH(MID(";"&'CASE DATA'!$F10&";",ROW($1:$99),1),";")),"",ROW($1:$99)+1),COLUMN(G10)),SMALL(IF(ISERROR(SEARCH(MID(";"&'CASE DATA'!$F10&";",ROW($1:$99),1),";")),"",ROW($1:$99)),COLUMN(G9)+1)-SMALL(IF(ISERROR(SEARCH(MID(";"&'CASE DATA'!$F10&";",ROW($1:$99),1),";")),"",ROW($1:$99)),COLUMN(G9))-1)} | AC10: {=MID(";"&'CASE DATA'!$F10&";",SMALL(IF(ISERROR(SEARCH(MID(";"&'CASE DATA'!$F10&";",ROW($1:$99),1),";")),"",ROW($1:$99)+1),COLUMN(H10)),SMALL(IF(ISERROR(SEARCH(MID(";"&'CASE DATA'!$F10&";",ROW($1:$99),1),";")),"",ROW($1:$99)),COLUMN(H9)+1)-SMALL(IF(ISERROR(SEARCH(MID(";"&'CASE DATA'!$F10&";",ROW($1:$99),1),";")),"",ROW($1:$99)),COLUMN(H9))-1)} | AD10: {=MID(";"&'CASE DATA'!$F10&";",SMALL(IF(ISERROR(SEARCH(MID(";"&'CASE DATA'!$F10&";",ROW($1:$99),1),";")),"",ROW($1:$99)+1),COLUMN(I10)),SMALL(IF(ISERROR(SEARCH(MID(";"&'CASE DATA'!$F10&";",ROW($1:$99),1),";")),"",ROW($1:$99)),COLUMN(I9)+1)-SMALL(IF(ISERROR(SEARCH(MID(";"&'CASE DATA'!$F10&";",ROW($1:$99),1),";")),"",ROW($1:$99)),COLUMN(I9))-1)} | AE10: {=MID(";"&'CASE DATA'!$F10&";",SMALL(IF(ISERROR(SEARCH(MID(";"&'CASE DATA'!$F10&";",ROW($1:$99),1),";")),"",ROW($1:$99)+1),COLUMN(J10)),SMALL(IF(ISERROR(SEARCH(MID(";"&'CASE DATA'!$F10&";",ROW($1:$99),1),";")),"",ROW($1:$99)),COLUMN(J9)+1)-SMALL(IF(ISERROR(SEARCH(MID(";"&'CASE DATA'!$F10&";",ROW($1:$99),1),";")),"",ROW($1:$99)),COLUMN(J9))-1)} | AF10: {=MID(";"&'CASE DATA'!$F10&";",SMALL(IF(ISERROR(SEARCH(MID(";"&'CASE DATA'!$F10&";",ROW($1:$99),1),";")),"",ROW($1:$99)+1),COLUMN(K10)),SMALL(IF(ISERROR(SEARCH(MID(";"&'CASE DATA'!$F10&";",ROW($1:$99),1),";")),"",ROW($1:$99)),COLUMN(K9)+1)-SMALL(IF(ISERROR(SEARCH(MID(";"&'CASE DATA'!$F10&";",ROW($1:$99),1),";")),"",ROW($1:$99)),COLUMN(K9))-1)} | ... AH10: {=MID(";"&'CASE DATA'!$F10&";",SMALL(IF(ISERROR(SEARCH(MID(";"&'CASE DATA'!$F10&";",ROW($1:$99),1),";")),"",ROW($1:$99)+1),COLUMN(M10)),SMALL(IF(ISERROR(SEARCH(MID(";"&'CASE DATA'!$F10&";",ROW($1:$99),1),";")),"",ROW($1:$99)),COLUMN(M9)+1)-SMALL(IF(ISERROR(SEARCH(MID(";"&'CASE DATA'!$F10&";",ROW($1:$99),1),";")),"",ROW($1:$99)),COLUMN(M9))-1)}
T11: =SUM(J11:S11) -> 0 | W11: {=MID(";"&'CASE DATA'!$F11&";",SMALL(IF(ISERROR(SEARCH(MID(";"&'CASE DATA'!$F11&";",ROW($1:$99),1),";")),"",ROW($1:$99)+1),COLUMN(A11)),SMALL(IF(ISERROR(SEARCH(MID(";"&'CASE DATA'!$F11&";",ROW($1:$99),1),";")),"",ROW($1:$99)),COLUMN(A10)+1)-SMALL(IF(ISERROR(SEARCH(MID(";"&'CASE DATA'!$F11&";",ROW($1:$99),1),";")),"",ROW($1:$99)),COLUMN(A10))-1)} | X11: {=MID(";"&'CASE DATA'!$F11&";",SMALL(IF(ISERROR(SEARCH(MID(";"&'CASE DATA'!$F11&";",ROW($1:$99),1),";")),"",ROW($1:$99)+1),COLUMN(B11)),SMALL(IF(ISERROR(SEARCH(MID(";"&'CASE DATA'!$F11&";",ROW($1:$99),1),";")),"",ROW($1:$99)),COLUMN(B10)+1)-SMALL(IF(ISERROR(SEARCH(MID(";"&'CASE DATA'!$F11&";",ROW($1:$99),1),";")),"",ROW($1:$99)),COLUMN(B10))-1)} | Y11: {=MID(";"&'CASE DATA'!$F11&";",SMALL(IF(ISERROR(SEARCH(MID(";"&'CASE DATA'!$F11&";",ROW($1:$99),1),";")),"",ROW($1:$99)+1),COLUMN(D11)),SMALL(IF(ISERROR(SEARCH(MID(";"&'CASE DATA'!$F11&";",ROW($1:$99),1),";")),"",ROW($1:$99)),COLUMN(D10)+1)-SMALL(IF(ISERROR(SEARCH(MID(";"&'CASE DATA'!$F11&";",ROW($1:$99),1),";")),"",ROW($1:$99)),COLUMN(D10))-1)} | Z11: {=MID(";"&'CASE DATA'!$F11&";",SMALL(IF(ISERROR(SEARCH(MID(";"&'CASE DATA'!$F11&";",ROW($1:$99),1),";")),"",ROW($1:$99)+1),COLUMN(E11)),SMALL(IF(ISERROR(SEARCH(MID(";"&'CASE DATA'!$F11&";",ROW($1:$99),1),";")),"",ROW($1:$99)),COLUMN(E10)+1)-SMALL(IF(ISERROR(SEARCH(MID(";"&'CASE DATA'!$F11&";",ROW($1:$99),1),";")),"",ROW($1:$99)),COLUMN(E10))-1)} | AA11: {=MID(";"&'CASE DATA'!$F11&";",SMALL(IF(ISERROR(SEARCH(MID(";"&'CASE DATA'!$F11&";",ROW($1:$99),1),";")),"",ROW($1:$99)+1),COLUMN(F11)),SMALL(IF(ISERROR(SEARCH(MID(";"&'CASE DATA'!$F11&";",ROW($1:$99),1),";")),"",ROW($1:$99)),COLUMN(F10)+1)-SMALL(IF(ISERROR(SEARCH(MID(";"&'CASE DATA'!$F11&";",ROW($1:$99),1),";")),"",ROW($1:$99)),COLUMN(F10))-1)} | AB11: {=MID(";"&'CASE DATA'!$F11&";",SMALL(IF(ISERROR(SEARCH(MID(";"&'CASE DATA'!$F11&";",ROW($1:$99),1),";")),"",ROW($1:$99)+1),COLUMN(G11)),SMALL(IF(ISERROR(SEARCH(MID(";"&'CASE DATA'!$F11&";",ROW($1:$99),1),";")),"",ROW($1:$99)),COLUMN(G10)+1)-SMALL(IF(ISERROR(SEARCH(MID(";"&'CASE DATA'!$F11&";",ROW($1:$99),1),";")),"",ROW($1:$99)),COLUMN(G10))-1)} | AC11: {=MID(";"&'CASE DATA'!$F11&";",SMALL(IF(ISERROR(SEARCH(MID(";"&'CASE DATA'!$F11&";",ROW($1:$99),1),";")),"",ROW($1:$99)+1),COLUMN(H11)),SMALL(IF(ISERROR(SEARCH(MID(";"&'CASE DATA'!$F11&";",ROW($1:$99),1),";")),"",ROW($1:$99)),COLUMN(H10)+1)-SMALL(IF(ISERROR(SEARCH(MID(";"&'CASE DATA'!$F11&";",ROW($1:$99),1),";")),"",ROW($1:$99)),COLUMN(H10))-1)} | AD11: {=MID(";"&'CASE DATA'!$F11&";",SMALL(IF(ISERROR(SEARCH(MID(";"&'CASE DATA'!$F11&";",ROW($1:$99),1),";")),"",ROW($1:$99)+1),COLUMN(I11)),SMALL(IF(ISERROR(SEARCH(MID(";"&'CASE DATA'!$F11&";",ROW($1:$99),1),";")),"",ROW($1:$99)),COLUMN(I10)+1)-SMALL(IF(ISERROR(SEARCH(MID(";"&'CASE DATA'!$F11&";",ROW($1:$99),1),";")),"",ROW($1:$99)),COLUMN(I10))-1)} | AE11: {=MID(";"&'CASE DATA'!$F11&";",SMALL(IF(ISERROR(SEARCH(MID(";"&'CASE DATA'!$F11&";",ROW($1:$99),1),";")),"",ROW($1:$99)+1),COLUMN(J11)),SMALL(IF(ISERROR(SEARCH(MID(";"&'CASE DATA'!$F11&";",ROW($1:$99),1),";")),"",ROW($1:$99)),COLUMN(J10)+1)-SMALL(IF(ISERROR(SEARCH(MID(";"&'CASE DATA'!$F11&";",ROW($1:$99),1),";")),"",ROW($1:$99)),COLUMN(J10))-1)} | AF11: {=MID(";"&'CASE DATA'!$F11&";",SMALL(IF(ISERROR(SEARCH(MID(";"&'CASE DATA'!$F11&";",ROW($1:$99),1),";")),"",ROW($1:$99)+1),COLUMN(K11)),SMALL(IF(ISERROR(SEARCH(MID(";"&'CASE DATA'!$F11&";",ROW($1:$99),1),";")),"",ROW($1:$99)),COLUMN(K10)+1)-SMALL(IF(ISERROR(SEARCH(MID(";"&'CASE DATA'!$F11&";",ROW($1:$99),1),";")),"",ROW($1:$99)),COLUMN(K10))-1)} | ... AH11: {=MID(";"&'CASE DATA'!$F11&";",SMALL(IF(ISERROR(SEARCH(MID(";"&'CASE DATA'!$F11&";",ROW($1:$99),1),";")),"",ROW($1:$99)+1),COLUMN(M11)),SMALL(IF(ISERROR(SEARCH(MID(";"&'CASE DATA'!$F11&";",ROW($1:$99),1),";")),"",ROW($1:$99)),COLUMN(M10)+1)-SMALL(IF(ISERROR(SEARCH(MID(";"&'CASE DATA'!$F11&";",ROW($1:$99),1),";")),"",ROW($1:$99)),COLUMN(M10))-1)}
T12: =SUM(J12:S12) -> 0 | W12: {=MID(";"&'CASE DATA'!$F12&";",SMALL(IF(ISERROR(SEARCH(MID(";"&'CASE DATA'!$F12&";",ROW($1:$99),1),";")),"",ROW($1:$99)+1),COLUMN(A12)),SMALL(IF(ISERROR(SEARCH(MID(";"&'CASE DATA'!$F12&";",ROW($1:$99),1),";")),"",ROW($1:$99)),COLUMN(A11)+1)-SMALL(IF(ISERROR(SEARCH(MID(";"&'CASE DATA'!$F12&";",ROW($1:$99),1),";")),"",ROW($1:$99)),COLUMN(A11))-1)} | X12: {=MID(";"&'CASE DATA'!$F12&";",SMALL(IF(ISERROR(SEARCH(MID(";"&'CASE DATA'!$F12&";",ROW($1:$99),1),";")),"",ROW($1:$99)+1),COLUMN(B12)),SMALL(IF(ISERROR(SEARCH(MID(";"&'CASE DATA'!$F12&";",ROW($1:$99),1),";")),"",ROW($1:$99)),COLUMN(B11)+1)-SMALL(IF(ISERROR(SEARCH(MID(";"&'CASE DATA'!$F12&";",ROW($1:$99),1),";")),"",ROW($1:$99)),COLUMN(B11))-1)} | Y12: {=MID(";"&'CASE DATA'!$F12&";",SMALL(IF(ISERROR(SEARCH(MID(";"&'CASE DATA'!$F12&";",ROW($1:$99),1),";")),"",ROW($1:$99)+1),COLUMN(D12)),SMALL(IF(ISERROR(SEARCH(MID(";"&'CASE DATA'!$F12&";",ROW($1:$99),1),";")),"",ROW($1:$99)),COLUMN(D11)+1)-SMALL(IF(ISERROR(SEARCH(MID(";"&'CASE DATA'!$F12&";",ROW($1:$99),1),";")),"",ROW($1:$99)),COLUMN(D11))-1)} | Z12: {=MID(";"&'CASE DATA'!$F12&";",SMALL(IF(ISERROR(SEARCH(MID(";"&'CASE DATA'!$F12&";",ROW($1:$99),1),";")),"",ROW($1:$99)+1),COLUMN(E12)),SMALL(IF(ISERROR(SEARCH(MID(";"&'CASE DATA'!$F12&";",ROW($1:$99),1),";")),"",ROW($1:$99)),COLUMN(E11)+1)-SMALL(IF(ISERROR(SEARCH(MID(";"&'CASE DATA'!$F12&";",ROW($1:$99),1),";")),"",ROW($1:$99)),COLUMN(E11))-1)} | AA12: {=MID(";"&'CASE DATA'!$F12&";",SMALL(IF(ISERROR(SEARCH(MID(";"&'CASE DATA'!$F12&";",ROW($1:$99),1),";")),"",ROW($1:$99)+1),COLUMN(F12)),SMALL(IF(ISERROR(SEARCH(MID(";"&'CASE DATA'!$F12&";",ROW($1:$99),1),";")),"",ROW($1:$99)),COLUMN(F11)+1)-SMALL(IF(ISERROR(SEARCH(MID(";"&'CASE DATA'!$F12&";",ROW($1:$99),1),";")),"",ROW($1:$99)),COLUMN(F11))-1)} | AB12: {=MID(";"&'CASE DATA'!$F12&";",SMALL(IF(ISERROR(SEARCH(MID(";"&'CASE DATA'!$F12&";",ROW($1:$99),1),";")),"",ROW($1:$99)+1),COLUMN(G12)),SMALL(IF(ISERROR(SEARCH(MID(";"&'CASE DATA'!$F12&";",ROW($1:$99),1),";")),"",ROW($1:$99)),COLUMN(G11)+1)-SMALL(IF(ISERROR(SEARCH(MID(";"&'CASE DATA'!$F12&";",ROW($1:$99),1),";")),"",ROW($1:$99)),COLUMN(G11))-1)} | AC12: {=MID(";"&'CASE DATA'!$F12&";",SMALL(IF(ISERROR(SEARCH(MID(";"&'CASE DATA'!$F12&";",ROW($1:$99),1),";")),"",ROW($1:$99)+1),COLUMN(H12)),SMALL(IF(ISERROR(SEARCH(MID(";"&'CASE DATA'!$F12&";",ROW($1:$99),1),";")),"",ROW($1:$99)),COLUMN(H11)+1)-SMALL(IF(ISERROR(SEARCH(MID(";"&'CASE DATA'!$F12&";",ROW($1:$99),1),";")),"",ROW($1:$99)),COLUMN(H11))-1)} | AD12: {=MID(";"&'CASE DATA'!$F12&";",SMALL(IF(ISERROR(SEARCH(MID(";"&'CASE DATA'!$F12&";",ROW($1:$99),1),";")),"",ROW($1:$99)+1),COLUMN(I12)),SMALL(IF(ISERROR(SEARCH(MID(";"&'CASE DATA'!$F12&";",ROW($1:$99),1),";")),"",ROW($1:$99)),COLUMN(I11)+1)-SMALL(IF(ISERROR(SEARCH(MID(";"&'CASE DATA'!$F12&";",ROW($1:$99),1),";")),"",ROW($1:$99)),COLUMN(I11))-1)} | AE12: {=MID(";"&'CASE DATA'!$F12&";",SMALL(IF(ISERROR(SEARCH(MID(";"&'CASE DATA'!$F12&";",ROW($1:$99),1),";")),"",ROW($1:$99)+1),COLUMN(J12)),SMALL(IF(ISERROR(SEARCH(MID(";"&'CASE DATA'!$F12&";",ROW($1:$99),1),";")),"",ROW($1:$99)),COLUMN(J11)+1)-SMALL(IF(ISERROR(SEARCH(MID(";"&'CASE DATA'!$F12&";",ROW($1:$99),1),";")),"",ROW($1:$99)),COLUMN(J11))-1)} | AF12: {=MID(";"&'CASE DATA'!$F12&";",SMALL(IF(ISERROR(SEARCH(MID(";"&'CASE DATA'!$F12&";",ROW($1:$99),1),";")),"",ROW($1:$99)+1),COLUMN(K12)),SMALL(IF(ISERROR(SEARCH(MID(";"&'CASE DATA'!$F12&";",ROW($1:$99),1),";")),"",ROW($1:$99)),COLUMN(K11)+1)-SMALL(IF(ISERROR(SEARCH(MID(";"&'CASE DATA'!$F12&";",ROW($1:$99),1),";")),"",ROW($1:$99)),COLUMN(K11))-1)} | ... AH12: {=MID(";"&'CASE DATA'!$F12&";",SMALL(IF(ISERROR(SEARCH(MID(";"&'CASE DATA'!$F12&";",ROW($1:$99),1),";")),"",ROW($1:$99)+1),COLUMN(M12)),SMALL(IF(ISERROR(SEARCH(MID(";"&'CASE DATA'!$F12&";",ROW($1:$99),1),";")),"",ROW($1:$99)),COLUMN(M11)+1)-SMALL(IF(ISERROR(SEARCH(MID(";"&'CASE DATA'!$F12&";",ROW($1:$99),1),";")),"",ROW($1:$99)),COLUMN(M11))-1)}
T13: =SUM(J13:S13) -> 0 | W13: {=MID(";"&'CASE DATA'!$F13&";",SMALL(IF(ISERROR(SEARCH(MID(";"&'CASE DATA'!$F13&";",ROW($1:$99),1),";")),"",ROW($1:$99)+1),COLUMN(A13)),SMALL(IF(ISERROR(SEARCH(MID(";"&'CASE DATA'!$F13&";",ROW($1:$99),1),";")),"",ROW($1:$99)),COLUMN(A12)+1)-SMALL(IF(ISERROR(SEARCH(MID(";"&'CASE DATA'!$F13&";",ROW($1:$99),1),";")),"",ROW($1:$99)),COLUMN(A12))-1)} | X13: {=MID(";"&'CASE DATA'!$F13&";",SMALL(IF(ISERROR(SEARCH(MID(";"&'CASE DATA'!$F13&";",ROW($1:$99),1),";")),"",ROW($1:$99)+1),COLUMN(B13)),SMALL(IF(ISERROR(SEARCH(MID(";"&'CASE DATA'!$F13&";",ROW($1:$99),1),";")),"",ROW($1:$99)),COLUMN(B12)+1)-SMALL(IF(ISERROR(SEARCH(MID(";"&'CASE DATA'!$F13&";",ROW($1:$99),1),";")),"",ROW($1:$99)),COLUMN(B12))-1)} | Y13: {=MID(";"&'CASE DATA'!$F13&";",SMALL(IF(ISERROR(SEARCH(MID(";"&'CASE DATA'!$F13&";",ROW($1:$99),1),";")),"",ROW($1:$99)+1),COLUMN(D13)),SMALL(IF(ISERROR(SEARCH(MID(";"&'CASE DATA'!$F13&";",ROW($1:$99),1),";")),"",ROW($1:$99)),COLUMN(D12)+1)-SMALL(IF(ISERROR(SEARCH(MID(";"&'CASE DATA'!$F13&";",ROW($1:$99),1),";")),"",ROW($1:$99)),COLUMN(D12))-1)} | Z13: {=MID(";"&'CASE DATA'!$F13&";",SMALL(IF(ISERROR(SEARCH(MID(";"&'CASE DATA'!$F13&";",ROW($1:$99),1),";")),"",ROW($1:$99)+1),COLUMN(E13)),SMALL(IF(ISERROR(SEARCH(MID(";"&'CASE DATA'!$F13&";",ROW($1:$99),1),";")),"",ROW($1:$99)),COLUMN(E12)+1)-SMALL(IF(ISERROR(SEARCH(MID(";"&'CASE DATA'!$F13&";",ROW($1:$99),1),";")),"",ROW($1:$99)),COLUMN(E12))-1)} | AA13: {=MID(";"&'CASE DATA'!$F13&";",SMALL(IF(ISERROR(SEARCH(MID(";"&'CASE DATA'!$F13&";",ROW($1:$99),1),";")),"",ROW($1:$99)+1),COLUMN(F13)),SMALL(IF(ISERROR(SEARCH(MID(";"&'CASE DATA'!$F13&";",ROW($1:$99),1),";")),"",ROW($1:$99)),COLUMN(F12)+1)-SMALL(IF(ISERROR(SEARCH(MID(";"&'CASE DATA'!$F13&";",ROW($1:$99),1),";")),"",ROW($1:$99)),COLUMN(F12))-1)} | AB13: {=MID(";"&'CASE DATA'!$F13&";",SMALL(IF(ISERROR(SEARCH(MID(";"&'CASE DATA'!$F13&";",ROW($1:$99),1),";")),"",ROW($1:$99)+1),COLUMN(G13)),SMALL(IF(ISERROR(SEARCH(MID(";"&'CASE DATA'!$F13&";",ROW($1:$99),1),";")),"",ROW($1:$99)),COLUMN(G12)+1)-SMALL(IF(ISERROR(SEARCH(MID(";"&'CASE DATA'!$F13&";",ROW($1:$99),1),";")),"",ROW($1:$99)),COLUMN(G12))-1)} | AC13: {=MID(";"&'CASE DATA'!$F13&";",SMALL(IF(ISERROR(SEARCH(MID(";"&'CASE DATA'!$F13&";",ROW($1:$99),1),";")),"",ROW($1:$99)+1),COLUMN(H13)),SMALL(IF(ISERROR(SEARCH(MID(";"&'CASE DATA'!$F13&";",ROW($1:$99),1),";")),"",ROW($1:$99)),COLUMN(H12)+1)-SMALL(IF(ISERROR(SEARCH(MID(";"&'CASE DATA'!$F13&";",ROW($1:$99),1),";")),"",ROW($1:$99)),COLUMN(H12))-1)} | AD13: {=MID(";"&'CASE DATA'!$F13&";",SMALL(IF(ISERROR(SEARCH(MID(";"&'CASE DATA'!$F13&";",ROW($1:$99),1),";")),"",ROW($1:$99)+1),COLUMN(I13)),SMALL(IF(ISERROR(SEARCH(MID(";"&'CASE DATA'!$F13&";",ROW($1:$99),1),";")),"",ROW($1:$99)),COLUMN(I12)+1)-SMALL(IF(ISERROR(SEARCH(MID(";"&'CASE DATA'!$F13&";",ROW($1:$99),1),";")),"",ROW($1:$99)),COLUMN(I12))-1)} | AE13: {=MID(";"&'CASE DATA'!$F13&";",SMALL(IF(ISERROR(SEARCH(MID(";"&'CASE DATA'!$F13&";",ROW($1:$99),1),";")),"",ROW($1:$99)+1),COLUMN(J13)),SMALL(IF(ISERROR(SEARCH(MID(";"&'CASE DATA'!$F13&";",ROW($1:$99),1),";")),"",ROW($1:$99)),COLUMN(J12)+1)-SMALL(IF(ISERROR(SEARCH(MID(";"&'CASE DATA'!$F13&";",ROW($1:$99),1),";")),"",ROW($1:$99)),COLUMN(J12))-1)} | AF13: {=MID(";"&'CASE DATA'!$F13&";",SMALL(IF(ISERROR(SEARCH(MID(";"&'CASE DATA'!$F13&";",ROW($1:$99),1),";")),"",ROW($1:$99)+1),COLUMN(K13)),SMALL(IF(ISERROR(SEARCH(MID(";"&'CASE DATA'!$F13&";",ROW($1:$99),1),";")),"",ROW($1:$99)),COLUMN(K12)+1)-SMALL(IF(ISERROR(SEARCH(MID(";"&'CASE DATA'!$F13&";",ROW($1:$99),1),";")),"",ROW($1:$99)),COLUMN(K12))-1)} | ... AH13: {=MID(";"&'CASE DATA'!$F13&";",SMALL(IF(ISERROR(SEARCH(MID(";"&'CASE DATA'!$F13&";",ROW($1:$99),1),";")),"",ROW($1:$99)+1),COLUMN(M13)),SMALL(IF(ISERROR(SEARCH(MID(";"&'CASE DATA'!$F13&";",ROW($1:$99),1),";")),"",ROW($1:$99)),COLUMN(M12)+1)-SMALL(IF(ISERROR(SEARCH(MID(";"&'CASE DATA'!$F13&";",ROW($1:$99),1),";")),"",ROW($1:$99)),COLUMN(M12))-1)}
T14: =SUM(J14:S14) -> 0 | W14: {=MID(";"&'CASE DATA'!$F14&";",SMALL(IF(ISERROR(SEARCH(MID(";"&'CASE DATA'!$F14&";",ROW($1:$99),1),";")),"",ROW($1:$99)+1),COLUMN(A14)),SMALL(IF(ISERROR(SEARCH(MID(";"&'CASE DATA'!$F14&";",ROW($1:$99),1),";")),"",ROW($1:$99)),COLUMN(A13)+1)-SMALL(IF(ISERROR(SEARCH(MID(";"&'CASE DATA'!$F14&";",ROW($1:$99),1),";")),"",ROW($1:$99)),COLUMN(A13))-1)} | X14: {=MID(";"&'CASE DATA'!$F14&";",SMALL(IF(ISERROR(SEARCH(MID(";"&'CASE DATA'!$F14&";",ROW($1:$99),1),";")),"",ROW($1:$99)+1),COLUMN(B14)),SMALL(IF(ISERROR(SEARCH(MID(";"&'CASE DATA'!$F14&";",ROW($1:$99),1),";")),"",ROW($1:$99)),COLUMN(B13)+1)-SMALL(IF(ISERROR(SEARCH(MID(";"&'CASE DATA'!$F14&";",ROW($1:$99),1),";")),"",ROW($1:$99)),COLUMN(B13))-1)} | Y14: {=MID(";"&'CASE DATA'!$F14&";",SMALL(IF(ISERROR(SEARCH(MID(";"&'CASE DATA'!$F14&";",ROW($1:$99),1),";")),"",ROW($1:$99)+1),COLUMN(D14)),SMALL(IF(ISERROR(SEARCH(MID(";"&'CASE DATA'!$F14&";",ROW($1:$99),1),";")),"",ROW($1:$99)),COLUMN(D13)+1)-SMALL(IF(ISERROR(SEARCH(MID(";"&'CASE DATA'!$F14&";",ROW($1:$99),1),";")),"",ROW($1:$99)),COLUMN(D13))-1)} | Z14: {=MID(";"&'CASE DATA'!$F14&";",SMALL(IF(ISERROR(SEARCH(MID(";"&'CASE DATA'!$F14&";",ROW($1:$99),1),";")),"",ROW($1:$99)+1),COLUMN(E14)),SMALL(IF(ISERROR(SEARCH(MID(";"&'CASE DATA'!$F14&";",ROW($1:$99),1),";")),"",ROW($1:$99)),COLUMN(E13)+1)-SMALL(IF(ISERROR(SEARCH(MID(";"&'CASE DATA'!$F14&";",ROW($1:$99),1),";")),"",ROW($1:$99)),COLUMN(E13))-1)} | AA14: {=MID(";"&'CASE DATA'!$F14&";",SMALL(IF(ISERROR(SEARCH(MID(";"&'CASE DATA'!$F14&";",ROW($1:$99),1),";")),"",ROW($1:$99)+1),COLUMN(F14)),SMALL(IF(ISERROR(SEARCH(MID(";"&'CASE DATA'!$F14&";",ROW($1:$99),1),";")),"",ROW($1:$99)),COLUMN(F13)+1)-SMALL(IF(ISERROR(SEARCH(MID(";"&'CASE DATA'!$F14&";",ROW($1:$99),1),";")),"",ROW($1:$99)),COLUMN(F13))-1)} | AB14: {=MID(";"&'CASE DATA'!$F14&";",SMALL(IF(ISERROR(SEARCH(MID(";"&'CASE DATA'!$F14&";",ROW($1:$99),1),";")),"",ROW($1:$99)+1),COLUMN(G14)),SMALL(IF(ISERROR(SEARCH(MID(";"&'CASE DATA'!$F14&";",ROW($1:$99),1),";")),"",ROW($1:$99)),COLUMN(G13)+1)-SMALL(IF(ISERROR(SEARCH(MID(";"&'CASE DATA'!$F14&";",ROW($1:$99),1),";")),"",ROW($1:$99)),COLUMN(G13))-1)} | AC14: {=MID(";"&'CASE DATA'!$F14&";",SMALL(IF(ISERROR(SEARCH(MID(";"&'CASE DATA'!$F14&";",ROW($1:$99),1),";")),"",ROW($1:$99)+1),COLUMN(H14)),SMALL(IF(ISERROR(SEARCH(MID(";"&'CASE DATA'!$F14&";",ROW($1:$99),1),";")),"",ROW($1:$99)),COLUMN(H13)+1)-SMALL(IF(ISERROR(SEARCH(MID(";"&'CASE DATA'!$F14&";",ROW($1:$99),1),";")),"",ROW($1:$99)),COLUMN(H13))-1)} | AD14: {=MID(";"&'CASE DATA'!$F14&";",SMALL(IF(ISERROR(SEARCH(MID(";"&'CASE DATA'!$F14&";",ROW($1:$99),1),";")),"",ROW($1:$99)+1),COLUMN(I14)),SMALL(IF(ISERROR(SEARCH(MID(";"&'CASE DATA'!$F14&";",ROW($1:$99),1),";")),"",ROW($1:$99)),COLUMN(I13)+1)-SMALL(IF(ISERROR(SEARCH(MID(";"&'CASE DATA'!$F14&";",ROW($1:$99),1),";")),"",ROW($1:$99)),COLUMN(I13))-1)} | AE14: {=MID(";"&'CASE DATA'!$F14&";",SMALL(IF(ISERROR(SEARCH(MID(";"&'CASE DATA'!$F14&";",ROW($1:$99),1),";")),"",ROW($1:$99)+1),COLUMN(J14)),SMALL(IF(ISERROR(SEARCH(MID(";"&'CASE DATA'!$F14&";",ROW($1:$99),1),";")),"",ROW($1:$99)),COLUMN(J13)+1)-SMALL(IF(ISERROR(SEARCH(MID(";"&'CASE DATA'!$F14&";",ROW($1:$99),1),";")),"",ROW($1:$99)),COLUMN(J13))-1)} | AF14: {=MID(";"&'CASE DATA'!$F14&";",SMALL(IF(ISERROR(SEARCH(MID(";"&'CASE DATA'!$F14&";",ROW($1:$99),1),";")),"",ROW($1:$99)+1),COLUMN(K14)),SMALL(IF(ISERROR(SEARCH(MID(";"&'CASE DATA'!$F14&";",ROW($1:$99),1),";")),"",ROW($1:$99)),COLUMN(K13)+1)-SMALL(IF(ISERROR(SEARCH(MID(";"&'CASE DATA'!$F14&";",ROW($1:$99),1),";")),"",ROW($1:$99)),COLUMN(K13))-1)} | ... AH14: {=MID(";"&'CASE DATA'!$F14&";",SMALL(IF(ISERROR(SEARCH(MID(";"&'CASE DATA'!$F14&";",ROW($1:$99),1),";")),"",ROW($1:$99)+1),COLUMN(M14)),SMALL(IF(ISERROR(SEARCH(MID(";"&'CASE DATA'!$F14&";",ROW($1:$99),1),";")),"",ROW($1:$99)),COLUMN(M13)+1)-SMALL(IF(ISERROR(SEARCH(MID(";"&'CASE DATA'!$F14&";",ROW($1:$99),1),";")),"",ROW($1:$99)),COLUMN(M13))-1)}
T15: =SUM(J15:S15) -> 0 | W15: {=MID(";"&'CASE DATA'!$F15&";",SMALL(IF(ISERROR(SEARCH(MID(";"&'CASE DATA'!$F15&";",ROW($1:$99),1),";")),"",ROW($1:$99)+1),COLUMN(A15)),SMALL(IF(ISERROR(SEARCH(MID(";"&'CASE DATA'!$F15&";",ROW($1:$99),1),";")),"",ROW($1:$99)),COLUMN(A14)+1)-SMALL(IF(ISERROR(SEARCH(MID(";"&'CASE DATA'!$F15&";",ROW($1:$99),1),";")),"",ROW($1:$99)),COLUMN(A14))-1)} | X15: {=MID(";"&'CASE DATA'!$F15&";",SMALL(IF(ISERROR(SEARCH(MID(";"&'CASE DATA'!$F15&";",ROW($1:$99),1),";")),"",ROW($1:$99)+1),COLUMN(B15)),SMALL(IF(ISERROR(SEARCH(MID(";"&'CASE DATA'!$F15&";",ROW($1:$99),1),";")),"",ROW($1:$99)),COLUMN(B14)+1)-SMALL(IF(ISERROR(SEARCH(MID(";"&'CASE DATA'!$F15&";",ROW($1:$99),1),";")),"",ROW($1:$99)),COLUMN(B14))-1)} | Y15: {=MID(";"&'CASE DATA'!$F15&";",SMALL(IF(ISERROR(SEARCH(MID(";"&'CASE DATA'!$F15&";",ROW($1:$99),1),";")),"",ROW($1:$99)+1),COLUMN(D15)),SMALL(IF(ISERROR(SEARCH(MID(";"&'CASE DATA'!$F15&";",ROW($1:$99),1),";")),"",ROW($1:$99)),COLUMN(D14)+1)-SMALL(IF(ISERROR(SEARCH(MID(";"&'CASE DATA'!$F15&";",ROW($1:$99),1),";")),"",ROW($1:$99)),COLUMN(D14))-1)} | Z15: {=MID(";"&'CASE DATA'!$F15&";",SMALL(IF(ISERROR(SEARCH(MID(";"&'CASE DATA'!$F15&";",ROW($1:$99),1),";")),"",ROW($1:$99)+1),COLUMN(E15)),SMALL(IF(ISERROR(SEARCH(MID(";"&'CASE DATA'!$F15&";",ROW($1:$99),1),";")),"",ROW($1:$99)),COLUMN(E14)+1)-SMALL(IF(ISERROR(SEARCH(MID(";"&'CASE DATA'!$F15&";",ROW($1:$99),1),";")),"",ROW($1:$99)),COLUMN(E14))-1)} | AA15: {=MID(";"&'CASE DATA'!$F15&";",SMALL(IF(ISERROR(SEARCH(MID(";"&'CASE DATA'!$F15&";",ROW($1:$99),1),";")),"",ROW($1:$99)+1),COLUMN(F15)),SMALL(IF(ISERROR(SEARCH(MID(";"&'CASE DATA'!$F15&";",ROW($1:$99),1),";")),"",ROW($1:$99)),COLUMN(F14)+1)-SMALL(IF(ISERROR(SEARCH(MID(";"&'CASE DATA'!$F15&";",ROW($1:$99),1),";")),"",ROW($1:$99)),COLUMN(F14))-1)} | AB15: {=MID(";"&'CASE DATA'!$F15&";",SMALL(IF(ISERROR(SEARCH(MID(";"&'CASE DATA'!$F15&";",ROW($1:$99),1),";")),"",ROW($1:$99)+1),COLUMN(G15)),SMALL(IF(ISERROR(SEARCH(MID(";"&'CASE DATA'!$F15&";",ROW($1:$99),1),";")),"",ROW($1:$99)),COLUMN(G14)+1)-SMALL(IF(ISERROR(SEARCH(MID(";"&'CASE DATA'!$F15&";",ROW($1:$99),1),";")),"",ROW($1:$99)),COLUMN(G14))-1)} | AC15: {=MID(";"&'CASE DATA'!$F15&";",SMALL(IF(ISERROR(SEARCH(MID(";"&'CASE DATA'!$F15&";",ROW($1:$99),1),";")),"",ROW($1:$99)+1),COLUMN(H15)),SMALL(IF(ISERROR(SEARCH(MID(";"&'CASE DATA'!$F15&";",ROW($1:$99),1),";")),"",ROW($1:$99)),COLUMN(H14)+1)-SMALL(IF(ISERROR(SEARCH(MID(";"&'CASE DATA'!$F15&";",ROW($1:$99),1),";")),"",ROW($1:$99)),COLUMN(H14))-1)} | AD15: {=MID(";"&'CASE DATA'!$F15&";",SMALL(IF(ISERROR(SEARCH(MID(";"&'CASE DATA'!$F15&";",ROW($1:$99),1),";")),"",ROW($1:$99)+1),COLUMN(I15)),SMALL(IF(ISERROR(SEARCH(MID(";"&'CASE DATA'!$F15&";",ROW($1:$99),1),";")),"",ROW($1:$99)),COLUMN(I14)+1)-SMALL(IF(ISERROR(SEARCH(MID(";"&'CASE DATA'!$F15&";",ROW($1:$99),1),";")),"",ROW($1:$99)),COLUMN(I14))-1)} | AE15: {=MID(";"&'CASE DATA'!$F15&";",SMALL(IF(ISERROR(SEARCH(MID(";"&'CASE DATA'!$F15&";",ROW($1:$99),1),";")),"",ROW($1:$99)+1),COLUMN(J15)),SMALL(IF(ISERROR(SEARCH(MID(";"&'CASE DATA'!$F15&";",ROW($1:$99),1),";")),"",ROW($1:$99)),COLUMN(J14)+1)-SMALL(IF(ISERROR(SEARCH(MID(";"&'CASE DATA'!$F15&";",ROW($1:$99),1),";")),"",ROW($1:$99)),COLUMN(J14))-1)} | AF15: {=MID(";"&'CASE DATA'!$F15&";",SMALL(IF(ISERROR(SEARCH(MID(";"&'CASE DATA'!$F15&";",ROW($1:$99),1),";")),"",ROW($1:$99)+1),COLUMN(K15)),SMALL(IF(ISERROR(SEARCH(MID(";"&'CASE DATA'!$F15&";",ROW($1:$99),1),";")),"",ROW($1:$99)),COLUMN(K14)+1)-SMALL(IF(ISERROR(SEARCH(MID(";"&'CASE DATA'!$F15&";",ROW($1:$99),1),";")),"",ROW($1:$99)),COLUMN(K14))-1)} | ... AH15: {=MID(";"&'CASE DATA'!$F15&";",SMALL(IF(ISERROR(SEARCH(MID(";"&'CASE DATA'!$F15&";",ROW($1:$99),1),";")),"",ROW($1:$99)+1),COLUMN(M15)),SMALL(IF(ISERROR(SEARCH(MID(";"&'CASE DATA'!$F15&";",ROW($1:$99),1),";")),"",ROW($1:$99)),COLUMN(M14)+1)-SMALL(IF(ISERROR(SEARCH(MID(";"&'CASE DATA'!$F15&";",ROW($1:$99),1),";")),"",ROW($1:$99)),COLUMN(M14))-1)}
T16: =SUM(J16:S16) -> 0 | W16: {=MID(";"&'CASE DATA'!$F16&";",SMALL(IF(ISERROR(SEARCH(MID(";"&'CASE DATA'!$F16&";",ROW($1:$99),1),";")),"",ROW($1:$99)+1),COLUMN(A16)),SMALL(IF(ISERROR(SEARCH(MID(";"&'CASE DATA'!$F16&";",ROW($1:$99),1),";")),"",ROW($1:$99)),COLUMN(A15)+1)-SMALL(IF(ISERROR(SEARCH(MID(";"&'CASE DATA'!$F16&";",ROW($1:$99),1),";")),"",ROW($1:$99)),COLUMN(A15))-1)} | X16: {=MID(";"&'CASE DATA'!$F16&";",SMALL(IF(ISERROR(SEARCH(MID(";"&'CASE DATA'!$F16&";",ROW($1:$99),1),";")),"",ROW($1:$99)+1),COLUMN(B16)),SMALL(IF(ISERROR(SEARCH(MID(";"&'CASE DATA'!$F16&";",ROW($1:$99),1),";")),"",ROW($1:$99)),COLUMN(B15)+1)-SMALL(IF(ISERROR(SEARCH(MID(";"&'CASE DATA'!$F16&";",ROW($1:$99),1),";")),"",ROW($1:$99)),COLUMN(B15))-1)} | Y16: {=MID(";"&'CASE DATA'!$F16&";",SMALL(IF(ISERROR(SEARCH(MID(";"&'CASE DATA'!$F16&";",ROW($1:$99),1),";")),"",ROW($1:$99)+1),COLUMN(D16)),SMALL(IF(ISERROR(SEARCH(MID(";"&'CASE DATA'!$F16&";",ROW($1:$99),1),";")),"",ROW($1:$99)),COLUMN(D15)+1)-SMALL(IF(ISERROR(SEARCH(MID(";"&'CASE DATA'!$F16&";",ROW($1:$99),1),";")),"",ROW($1:$99)),COLUMN(D15))-1)} | Z16: {=MID(";"&'CASE DATA'!$F16&";",SMALL(IF(ISERROR(SEARCH(MID(";"&'CASE DATA'!$F16&";",ROW($1:$99),1),";")),"",ROW($1:$99)+1),COLUMN(E16)),SMALL(IF(ISERROR(SEARCH(MID(";"&'CASE DATA'!$F16&";",ROW($1:$99),1),";")),"",ROW($1:$99)),COLUMN(E15)+1)-SMALL(IF(ISERROR(SEARCH(MID(";"&'CASE DATA'!$F16&";",ROW($1:$99),1),";")),"",ROW($1:$99)),COLUMN(E15))-1)} | AA16: {=MID(";"&'CASE DATA'!$F16&";",SMALL(IF(ISERROR(SEARCH(MID(";"&'CASE DATA'!$F16&";",ROW($1:$99),1),";")),"",ROW($1:$99)+1),COLUMN(F16)),SMALL(IF(ISERROR(SEARCH(MID(";"&'CASE DATA'!$F16&";",ROW($1:$99),1),";")),"",ROW($1:$99)),COLUMN(F15)+1)-SMALL(IF(ISERROR(SEARCH(MID(";"&'CASE DATA'!$F16&";",ROW($1:$99),1),";")),"",ROW($1:$99)),COLUMN(F15))-1)} | AB16: {=MID(";"&'CASE DATA'!$F16&";",SMALL(IF(ISERROR(SEARCH(MID(";"&'CASE DATA'!$F16&";",ROW($1:$99),1),";")),"",ROW($1:$99)+1),COLUMN(G16)),SMALL(IF(ISERROR(SEARCH(MID(";"&'CASE DATA'!$F16&";",ROW($1:$99),1),";")),"",ROW($1:$99)),COLUMN(G15)+1)-SMALL(IF(ISERROR(SEARCH(MID(";"&'CASE DATA'!$F16&";",ROW($1:$99),1),";")),"",ROW($1:$99)),COLUMN(G15))-1)} | AC16: {=MID(";"&'CASE DATA'!$F16&";",SMALL(IF(ISERROR(SEARCH(MID(";"&'CASE DATA'!$F16&";",ROW($1:$99),1),";")),"",ROW($1:$99)+1),COLUMN(H16)),SMALL(IF(ISERROR(SEARCH(MID(";"&'CASE DATA'!$F16&";",ROW($1:$99),1),";")),"",ROW($1:$99)),COLUMN(H15)+1)-SMALL(IF(ISERROR(SEARCH(MID(";"&'CASE DATA'!$F16&";",ROW($1:$99),1),";")),"",ROW($1:$99)),COLUMN(H15))-1)} | AD16: {=MID(";"&'CASE DATA'!$F16&";",SMALL(IF(ISERROR(SEARCH(MID(";"&'CASE DATA'!$F16&";",ROW($1:$99),1),";")),"",ROW($1:$99)+1),COLUMN(I16)),SMALL(IF(ISERROR(SEARCH(MID(";"&'CASE DATA'!$F16&";",ROW($1:$99),1),";")),"",ROW($1:$99)),COLUMN(I15)+1)-SMALL(IF(ISERROR(SEARCH(MID(";"&'CASE DATA'!$F16&";",ROW($1:$99),1),";")),"",ROW($1:$99)),COLUMN(I15))-1)} | AE16: {=MID(";"&'CASE DATA'!$F16&";",SMALL(IF(ISERROR(SEARCH(MID(";"&'CASE DATA'!$F16&";",ROW($1:$99),1),";")),"",ROW($1:$99)+1),COLUMN(J16)),SMALL(IF(ISERROR(SEARCH(MID(";"&'CASE DATA'!$F16&";",ROW($1:$99),1),";")),"",ROW($1:$99)),COLUMN(J15)+1)-SMALL(IF(ISERROR(SEARCH(MID(";"&'CASE DATA'!$F16&";",ROW($1:$99),1),";")),"",ROW($1:$99)),COLUMN(J15))-1)} | AF16: {=MID(";"&'CASE DATA'!$F16&";",SMALL(IF(ISERROR(SEARCH(MID(";"&'CASE DATA'!$F16&";",ROW($1:$99),1),";")),"",ROW($1:$99)+1),COLUMN(K16)),SMALL(IF(ISERROR(SEARCH(MID(";"&'CASE DATA'!$F16&";",ROW($1:$99),1),";")),"",ROW($1:$99)),COLUMN(K15)+1)-SMALL(IF(ISERROR(SEARCH(MID(";"&'CASE DATA'!$F16&";",ROW($1:$99),1),";")),"",ROW($1:$99)),COLUMN(K15))-1)} | ... AH16: {=MID(";"&'CASE DATA'!$F16&";",SMALL(IF(ISERROR(SEARCH(MID(";"&'CASE DATA'!$F16&";",ROW($1:$99),1),";")),"",ROW($1:$99)+1),COLUMN(M16)),SMALL(IF(ISERROR(SEARCH(MID(";"&'CASE DATA'!$F16&";",ROW($1:$99),1),";")),"",ROW($1:$99)),COLUMN(M15)+1)-SMALL(IF(ISERROR(SEARCH(MID(";"&'CASE DATA'!$F16&";",ROW($1:$99),1),";")),"",ROW($1:$99)),COLUMN(M15))-1)}
T17: =SUM(J17:S17) -> 0 | W17: {=MID(";"&'CASE DATA'!$F17&";",SMALL(IF(ISERROR(SEARCH(MID(";"&'CASE DATA'!$F17&";",ROW($1:$99),1),";")),"",ROW($1:$99)+1),COLUMN(A17)),SMALL(IF(ISERROR(SEARCH(MID(";"&'CASE DATA'!$F17&";",ROW($1:$99),1),";")),"",ROW($1:$99)),COLUMN(A16)+1)-SMALL(IF(ISERROR(SEARCH(MID(";"&'CASE DATA'!$F17&";",ROW($1:$99),1),";")),"",ROW($1:$99)),COLUMN(A16))-1)} | X17: {=MID(";"&'CASE DATA'!$F17&";",SMALL(IF(ISERROR(SEARCH(MID(";"&'CASE DATA'!$F17&";",ROW($1:$99),1),";")),"",ROW($1:$99)+1),COLUMN(B17)),SMALL(IF(ISERROR(SEARCH(MID(";"&'CASE DATA'!$F17&";",ROW($1:$99),1),";")),"",ROW($1:$99)),COLUMN(B16)+1)-SMALL(IF(ISERROR(SEARCH(MID(";"&'CASE DATA'!$F17&";",ROW($1:$99),1),";")),"",ROW($1:$99)),COLUMN(B16))-1)} | Y17: {=MID(";"&'CASE DATA'!$F17&";",SMALL(IF(ISERROR(SEARCH(MID(";"&'CASE DATA'!$F17&";",ROW($1:$99),1),";")),"",ROW($1:$99)+1),COLUMN(D17)),SMALL(IF(ISERROR(SEARCH(MID(";"&'CASE DATA'!$F17&";",ROW($1:$99),1),";")),"",ROW($1:$99)),COLUMN(D16)+1)-SMALL(IF(ISERROR(SEARCH(MID(";"&'CASE DATA'!$F17&";",ROW($1:$99),1),";")),"",ROW($1:$99)),COLUMN(D16))-1)} | Z17: {=MID(";"&'CASE DATA'!$F17&";",SMALL(IF(ISERROR(SEARCH(MID(";"&'CASE DATA'!$F17&";",ROW($1:$99),1),";")),"",ROW($1:$99)+1),COLUMN(E17)),SMALL(IF(ISERROR(SEARCH(MID(";"&'CASE DATA'!$F17&";",ROW($1:$99),1),";")),"",ROW($1:$99)),COLUMN(E16)+1)-SMALL(IF(ISERROR(SEARCH(MID(";"&'CASE DATA'!$F17&";",ROW($1:$99),1),";")),"",ROW($1:$99)),COLUMN(E16))-1)} | AA17: {=MID(";"&'CASE DATA'!$F17&";",SMALL(IF(ISERROR(SEARCH(MID(";"&'CASE DATA'!$F17&";",ROW($1:$99),1),";")),"",ROW($1:$99)+1),COLUMN(F17)),SMALL(IF(ISERROR(SEARCH(MID(";"&'CASE DATA'!$F17&";",ROW($1:$99),1),";")),"",ROW($1:$99)),COLUMN(F16)+1)-SMALL(IF(ISERROR(SEARCH(MID(";"&'CASE DATA'!$F17&";",ROW($1:$99),1),";")),"",ROW($1:$99)),COLUMN(F16))-1)} | AB17: {=MID(";"&'CASE DATA'!$F17&";",SMALL(IF(ISERROR(SEARCH(MID(";"&'CASE DATA'!$F17&";",ROW($1:$99),1),";")),"",ROW($1:$99)+1),COLUMN(G17)),SMALL(IF(ISERROR(SEARCH(MID(";"&'CASE DATA'!$F17&";",ROW($1:$99),1),";")),"",ROW($1:$99)),COLUMN(G16)+1)-SMALL(IF(ISERROR(SEARCH(MID(";"&'CASE DATA'!$F17&";",ROW($1:$99),1),";")),"",ROW($1:$99)),COLUMN(G16))-1)} | AC17: {=MID(";"&'CASE DATA'!$F17&";",SMALL(IF(ISERROR(SEARCH(MID(";"&'CASE DATA'!$F17&";",ROW($1:$99),1),";")),"",ROW($1:$99)+1),COLUMN(H17)),SMALL(IF(ISERROR(SEARCH(MID(";"&'CASE DATA'!$F17&";",ROW($1:$99),1),";")),"",ROW($1:$99)),COLUMN(H16)+1)-SMALL(IF(ISERROR(SEARCH(MID(";"&'CASE DATA'!$F17&";",ROW($1:$99),1),";")),"",ROW($1:$99)),COLUMN(H16))-1)} | AD17: {=MID(";"&'CASE DATA'!$F17&";",SMALL(IF(ISERROR(SEARCH(MID(";"&'CASE DATA'!$F17&";",ROW($1:$99),1),";")),"",ROW($1:$99)+1),COLUMN(I17)),SMALL(IF(ISERROR(SEARCH(MID(";"&'CASE DATA'!$F17&";",ROW($1:$99),1),";")),"",ROW($1:$99)),COLUMN(I16)+1)-SMALL(IF(ISERROR(SEARCH(MID(";"&'CASE DATA'!$F17&";",ROW($1:$99),1),";")),"",ROW($1:$99)),COLUMN(I16))-1)} | AE17: {=MID(";"&'CASE DATA'!$F17&";",SMALL(IF(ISERROR(SEARCH(MID(";"&'CASE DATA'!$F17&";",ROW($1:$99),1),";")),"",ROW($1:$99)+1),COLUMN(J17)),SMALL(IF(ISERROR(SEARCH(MID(";"&'CASE DATA'!$F17&";",ROW($1:$99),1),";")),"",ROW($1:$99)),COLUMN(J16)+1)-SMALL(IF(ISERROR(SEARCH(MID(";"&'CASE DATA'!$F17&";",ROW($1:$99),1),";")),"",ROW($1:$99)),COLUMN(J16))-1)} | AF17: {=MID(";"&'CASE DATA'!$F17&";",SMALL(IF(ISERROR(SEARCH(MID(";"&'CASE DATA'!$F17&";",ROW($1:$99),1),";")),"",ROW($1:$99)+1),COLUMN(K17)),SMALL(IF(ISERROR(SEARCH(MID(";"&'CASE DATA'!$F17&";",ROW($1:$99),1),";")),"",ROW($1:$99)),COLUMN(K16)+1)-SMALL(IF(ISERROR(SEARCH(MID(";"&'CASE DATA'!$F17&";",ROW($1:$99),1),";")),"",ROW($1:$99)),COLUMN(K16))-1)} | ... AH17: {=MID(";"&'CASE DATA'!$F17&";",SMALL(IF(ISERROR(SEARCH(MID(";"&'CASE DATA'!$F17&";",ROW($1:$99),1),";")),"",ROW($1:$99)+1),COLUMN(M17)),SMALL(IF(ISERROR(SEARCH(MID(";"&'CASE DATA'!$F17&";",ROW($1:$99),1),";")),"",ROW($1:$99)),COLUMN(M16)+1)-SMALL(IF(ISERROR(SEARCH(MID(";"&'CASE DATA'!$F17&";",ROW($1:$99),1),";")),"",ROW($1:$99)),COLUMN(M16))-1)}
T18: =SUM(J18:S18) -> 0 | W18: {=MID(";"&'CASE DATA'!$F18&";",SMALL(IF(ISERROR(SEARCH(MID(";"&'CASE DATA'!$F18&";",ROW($1:$99),1),";")),"",ROW($1:$99)+1),COLUMN(A18)),SMALL(IF(ISERROR(SEARCH(MID(";"&'CASE DATA'!$F18&";",ROW($1:$99),1),";")),"",ROW($1:$99)),COLUMN(A17)+1)-SMALL(IF(ISERROR(SEARCH(MID(";"&'CASE DATA'!$F18&";",ROW($1:$99),1),";")),"",ROW($1:$99)),COLUMN(A17))-1)} | X18: {=MID(";"&'CASE DATA'!$F18&";",SMALL(IF(ISERROR(SEARCH(MID(";"&'CASE DATA'!$F18&";",ROW($1:$99),1),";")),"",ROW($1:$99)+1),COLUMN(B18)),SMALL(IF(ISERROR(SEARCH(MID(";"&'CASE DATA'!$F18&";",ROW($1:$99),1),";")),"",ROW($1:$99)),COLUMN(B17)+1)-SMALL(IF(ISERROR(SEARCH(MID(";"&'CASE DATA'!$F18&";",ROW($1:$99),1),";")),"",ROW($1:$99)),COLUMN(B17))-1)} | Y18: {=MID(";"&'CASE DATA'!$F18&";",SMALL(IF(ISERROR(SEARCH(MID(";"&'CASE DATA'!$F18&";",ROW($1:$99),1),";")),"",ROW($1:$99)+1),COLUMN(D18)),SMALL(IF(ISERROR(SEARCH(MID(";"&'CASE DATA'!$F18&";",ROW($1:$99),1),";")),"",ROW($1:$99)),COLUMN(D17)+1)-SMALL(IF(ISERROR(SEARCH(MID(";"&'CASE DATA'!$F18&";",ROW($1:$99),1),";")),"",ROW($1:$99)),COLUMN(D17))-1)} | Z18: {=MID(";"&'CASE DATA'!$F18&";",SMALL(IF(ISERROR(SEARCH(MID(";"&'CASE DATA'!$F18&";",ROW($1:$99),1),";")),"",ROW($1:$99)+1),COLUMN(E18)),SMALL(IF(ISERROR(SEARCH(MID(";"&'CASE DATA'!$F18&";",ROW($1:$99),1),";")),"",ROW($1:$99)),COLUMN(E17)+1)-SMALL(IF(ISERROR(SEARCH(MID(";"&'CASE DATA'!$F18&";",ROW($1:$99),1),";")),"",ROW($1:$99)),COLUMN(E17))-1)} | AA18: {=MID(";"&'CASE DATA'!$F18&";",SMALL(IF(ISERROR(SEARCH(MID(";"&'CASE DATA'!$F18&";",ROW($1:$99),1),";")),"",ROW($1:$99)+1),COLUMN(F18)),SMALL(IF(ISERROR(SEARCH(MID(";"&'CASE DATA'!$F18&";",ROW($1:$99),1),";")),"",ROW($1:$99)),COLUMN(F17)+1)-SMALL(IF(ISERROR(SEARCH(MID(";"&'CASE DATA'!$F18&";",ROW($1:$99),1),";")),"",ROW($1:$99)),COLUMN(F17))-1)} | AB18: {=MID(";"&'CASE DATA'!$F18&";",SMALL(IF(ISERROR(SEARCH(MID(";"&'CASE DATA'!$F18&";",ROW($1:$99),1),";")),"",ROW($1:$99)+1),COLUMN(G18)),SMALL(IF(ISERROR(SEARCH(MID(";"&'CASE DATA'!$F18&";",ROW($1:$99),1),";")),"",ROW($1:$99)),COLUMN(G17)+1)-SMALL(IF(ISERROR(SEARCH(MID(";"&'CASE DATA'!$F18&";",ROW($1:$99),1),";")),"",ROW($1:$99)),COLUMN(G17))-1)} | AC18: {=MID(";"&'CASE DATA'!$F18&";",SMALL(IF(ISERROR(SEARCH(MID(";"&'CASE DATA'!$F18&";",ROW($1:$99),1),";")),"",ROW($1:$99)+1),COLUMN(H18)),SMALL(IF(ISERROR(SEARCH(MID(";"&'CASE DATA'!$F18&";",ROW($1:$99),1),";")),"",ROW($1:$99)),COLUMN(H17)+1)-SMALL(IF(ISERROR(SEARCH(MID(";"&'CASE DATA'!$F18&";",ROW($1:$99),1),";")),"",ROW($1:$99)),COLUMN(H17))-1)} | AD18: {=MID(";"&'CASE DATA'!$F18&";",SMALL(IF(ISERROR(SEARCH(MID(";"&'CASE DATA'!$F18&";",ROW($1:$99),1),";")),"",ROW($1:$99)+1),COLUMN(I18)),SMALL(IF(ISERROR(SEARCH(MID(";"&'CASE DATA'!$F18&";",ROW($1:$99),1),";")),"",ROW($1:$99)),COLUMN(I17)+1)-SMALL(IF(ISERROR(SEARCH(MID(";"&'CASE DATA'!$F18&";",ROW($1:$99),1),";")),"",ROW($1:$99)),COLUMN(I17))-1)} | AE18: {=MID(";"&'CASE DATA'!$F18&";",SMALL(IF(ISERROR(SEARCH(MID(";"&'CASE DATA'!$F18&";",ROW($1:$99),1),";")),"",ROW($1:$99)+1),COLUMN(J18)),SMALL(IF(ISERROR(SEARCH(MID(";"&'CASE DATA'!$F18&";",ROW($1:$99),1),";")),"",ROW($1:$99)),COLUMN(J17)+1)-SMALL(IF(ISERROR(SEARCH(MID(";"&'CASE DATA'!$F18&";",ROW($1:$99),1),";")),"",ROW($1:$99)),COLUMN(J17))-1)} | AF18: {=MID(";"&'CASE DATA'!$F18&";",SMALL(IF(ISERROR(SEARCH(MID(";"&'CASE DATA'!$F18&";",ROW($1:$99),1),";")),"",ROW($1:$99)+1),COLUMN(K18)),SMALL(IF(ISERROR(SEARCH(MID(";"&'CASE DATA'!$F18&";",ROW($1:$99),1),";")),"",ROW($1:$99)),COLUMN(K17)+1)-SMALL(IF(ISERROR(SEARCH(MID(";"&'CASE DATA'!$F18&";",ROW($1:$99),1),";")),"",ROW($1:$99)),COLUMN(K17))-1)} | ... AH18: {=MID(";"&'CASE DATA'!$F18&";",SMALL(IF(ISERROR(SEARCH(MID(";"&'CASE DATA'!$F18&";",ROW($1:$99),1),";")),"",ROW($1:$99)+1),COLUMN(M18)),SMALL(IF(ISERROR(SEARCH(MID(";"&'CASE DATA'!$F18&";",ROW($1:$99),1),";")),"",ROW($1:$99)),COLUMN(M17)+1)-SMALL(IF(ISERROR(SEARCH(MID(";"&'CASE DATA'!$F18&";",ROW($1:$99),1),";")),"",ROW($1:$99)),COLUMN(M17))-1)}
